2020/08/26 16:33:13 [info] 26#26 discovery started
2020/08/26 16:33:13 [notice] 26#26 module: python 3.7.3 "/usr/lib/unit/modules/python3.7.unit.so"
2020/08/26 16:33:13 [info] 1#1 controller started
2020/08/26 16:33:13 [notice] 1#1 process 26 exited with code 0
2020/08/26 16:33:13 [info] 28#28 router started
2020/08/26 16:33:13 [info] 28#28 OpenSSL 1.1.1d  10 Sep 2019, 1010104f
2020/08/26 16:33:13 [info] 29#29 "django-app" application started
2020/08/26 16:42:57 [info] 17#17 discovery started
2020/08/26 16:42:57 [notice] 17#17 module: python 3.7.3 "/usr/lib/unit/modules/python3.7.unit.so"
2020/08/26 16:42:57 [info] 1#1 controller started
2020/08/26 16:42:57 [notice] 1#1 process 17 exited with code 0
2020/08/26 16:42:57 [info] 19#19 router started
2020/08/26 16:42:57 [info] 19#19 OpenSSL 1.1.1d  10 Sep 2019, 1010104f
2020/08/26 16:42:57 [info] 20#20 "django-app" application started
2020/08/26 20:58:38 [info] 16#16 discovery started
2020/08/26 20:58:38 [notice] 16#16 module: python 3.7.3 "/usr/lib/unit/modules/python3.7.unit.so"
2020/08/26 20:58:38 [info] 1#1 controller started
2020/08/26 20:58:38 [notice] 1#1 process 16 exited with code 0
2020/08/26 20:58:38 [info] 18#18 router started
2020/08/26 20:58:38 [info] 18#18 OpenSSL 1.1.1d  10 Sep 2019, 1010104f
2020/08/26 20:58:38 [info] 19#19 "django-app" application started
2020/08/26 22:49:36 [info] 16#16 discovery started
2020/08/26 22:49:36 [notice] 16#16 module: python 3.7.3 "/usr/lib/unit/modules/python3.7.unit.so"
2020/08/26 22:49:36 [info] 1#1 controller started
2020/08/26 22:49:36 [notice] 1#1 process 16 exited with code 0
2020/08/26 22:49:36 [info] 18#18 router started
2020/08/26 22:49:36 [info] 18#18 OpenSSL 1.1.1d  10 Sep 2019, 1010104f
2020/08/26 22:49:36 [info] 19#19 "django-app" application started
2020/08/26 22:51:29 [notice] 1#1 process 17 exited with code 0
2020/08/26 22:51:29 [notice] 1#1 process 18 exited with code 0
2020/08/26 22:51:30 [notice] 1#1 process 19 exited with code 0
2020/08/27 11:00:35 [info] 16#16 discovery started
2020/08/27 11:00:35 [notice] 16#16 module: python 3.7.3 "/usr/lib/unit/modules/python3.7.unit.so"
2020/08/27 11:00:35 [info] 1#1 controller started
2020/08/27 11:00:35 [notice] 1#1 process 16 exited with code 0
2020/08/27 11:00:35 [info] 18#18 router started
2020/08/27 11:00:35 [info] 18#18 OpenSSL 1.1.1d  10 Sep 2019, 1010104f
2020/08/27 11:00:35 [info] 19#19 "django-app" application started
Internal Server Error: /admin/
Traceback (most recent call last):
  File "/usr/local/lib/python3.7/dist-packages/django/contrib/sessions/backends/base.py", line 199, in _get_session
    return self._session_cache
AttributeError: 'SessionStore' object has no attribute '_session_cache'

During handling of the above exception, another exception occurred:

Traceback (most recent call last):
  File "/usr/local/lib/python3.7/dist-packages/django/db/backends/utils.py", line 86, in _execute
    return self.cursor.execute(sql, params)
  File "/usr/local/lib/python3.7/dist-packages/django/db/backends/sqlite3/base.py", line 396, in execute
    return Database.Cursor.execute(self, query, params)
sqlite3.OperationalError: no such table: django_session

The above exception was the direct cause of the following exception:

Traceback (most recent call last):
  File "/usr/local/lib/python3.7/dist-packages/django/core/handlers/exception.py", line 34, in inner
    response = get_response(request)
  File "/usr/local/lib/python3.7/dist-packages/django/core/handlers/base.py", line 115, in _get_response
    response = self.process_exception_by_middleware(e, request)
  File "/usr/local/lib/python3.7/dist-packages/django/core/handlers/base.py", line 113, in _get_response
    response = wrapped_callback(request, *callback_args, **callback_kwargs)
  File "/usr/local/lib/python3.7/dist-packages/django/contrib/admin/sites.py", line 249, in wrapper
    return self.admin_view(view, cacheable)(*args, **kwargs)
  File "/usr/local/lib/python3.7/dist-packages/django/utils/decorators.py", line 130, in _wrapped_view
    response = view_func(request, *args, **kwargs)
  File "/usr/local/lib/python3.7/dist-packages/django/views/decorators/cache.py", line 44, in _wrapped_view_func
    response = view_func(request, *args, **kwargs)
  File "/usr/local/lib/python3.7/dist-packages/django/contrib/admin/sites.py", line 220, in inner
    if not self.has_permission(request):
  File "/usr/local/lib/python3.7/dist-packages/django/contrib/admin/sites.py", line 194, in has_permission
    return request.user.is_active and request.user.is_staff
  File "/usr/local/lib/python3.7/dist-packages/django/utils/functional.py", line 224, in inner
    self._setup()
  File "/usr/local/lib/python3.7/dist-packages/django/utils/functional.py", line 360, in _setup
    self._wrapped = self._setupfunc()
  File "/usr/local/lib/python3.7/dist-packages/django/contrib/auth/middleware.py", line 24, in <lambda>
    request.user = SimpleLazyObject(lambda: get_user(request))
  File "/usr/local/lib/python3.7/dist-packages/django/contrib/auth/middleware.py", line 12, in get_user
    request._cached_user = auth.get_user(request)
  File "/usr/local/lib/python3.7/dist-packages/django/contrib/auth/__init__.py", line 173, in get_user
    user_id = _get_user_session_key(request)
  File "/usr/local/lib/python3.7/dist-packages/django/contrib/auth/__init__.py", line 58, in _get_user_session_key
    return get_user_model()._meta.pk.to_python(request.session[SESSION_KEY])
  File "/usr/local/lib/python3.7/dist-packages/django/contrib/sessions/backends/base.py", line 64, in __getitem__
    return self._session[key]
  File "/usr/local/lib/python3.7/dist-packages/django/contrib/sessions/backends/base.py", line 204, in _get_session
    self._session_cache = self.load()
  File "/usr/local/lib/python3.7/dist-packages/django/contrib/sessions/backends/db.py", line 43, in load
    s = self._get_session_from_db()
  File "/usr/local/lib/python3.7/dist-packages/django/contrib/sessions/backends/db.py", line 34, in _get_session_from_db
    expire_date__gt=timezone.now()
  File "/usr/local/lib/python3.7/dist-packages/django/db/models/manager.py", line 82, in manager_method
    return getattr(self.get_queryset(), name)(*args, **kwargs)
  File "/usr/local/lib/python3.7/dist-packages/django/db/models/query.py", line 411, in get
    num = len(clone)
  File "/usr/local/lib/python3.7/dist-packages/django/db/models/query.py", line 258, in __len__
    self._fetch_all()
  File "/usr/local/lib/python3.7/dist-packages/django/db/models/query.py", line 1261, in _fetch_all
    self._result_cache = list(self._iterable_class(self))
  File "/usr/local/lib/python3.7/dist-packages/django/db/models/query.py", line 57, in __iter__
    results = compiler.execute_sql(chunked_fetch=self.chunked_fetch, chunk_size=self.chunk_size)
  File "/usr/local/lib/python3.7/dist-packages/django/db/models/sql/compiler.py", line 1137, in execute_sql
    cursor.execute(sql, params)
  File "/usr/local/lib/python3.7/dist-packages/django/db/backends/utils.py", line 100, in execute
    return super().execute(sql, params)
  File "/usr/local/lib/python3.7/dist-packages/django/db/backends/utils.py", line 68, in execute
    return self._execute_with_wrappers(sql, params, many=False, executor=self._execute)
  File "/usr/local/lib/python3.7/dist-packages/django/db/backends/utils.py", line 77, in _execute_with_wrappers
    return executor(sql, params, many, context)
  File "/usr/local/lib/python3.7/dist-packages/django/db/backends/utils.py", line 86, in _execute
    return self.cursor.execute(sql, params)
  File "/usr/local/lib/python3.7/dist-packages/django/db/utils.py", line 90, in __exit__
    raise dj_exc_value.with_traceback(traceback) from exc_value
  File "/usr/local/lib/python3.7/dist-packages/django/db/backends/utils.py", line 86, in _execute
    return self.cursor.execute(sql, params)
  File "/usr/local/lib/python3.7/dist-packages/django/db/backends/sqlite3/base.py", line 396, in execute
    return Database.Cursor.execute(self, query, params)
django.db.utils.OperationalError: no such table: django_session
2020/08/27 11:16:49 [notice] 1#1 process 17 exited with code 0
2020/08/27 11:16:49 [notice] 1#1 process 18 exited with code 0
2020/08/27 11:16:49 [notice] 1#1 process 19 exited with code 0
2020/08/27 16:14:42 [info] 23#23 discovery started
2020/08/27 16:14:42 [notice] 23#23 module: python 3.7.3 "/usr/lib/unit/modules/python3.7.unit.so"
2020/08/27 16:14:42 [info] 22#22 controller started
2020/08/27 16:14:42 [notice] 22#22 process 23 exited with code 0
2020/08/27 16:14:42 [info] 26#26 router started
2020/08/27 16:14:42 [info] 26#26 OpenSSL 1.1.1d  10 Sep 2019, 1010104f
2020/08/27 16:14:42 [info] 30#30 "django-app" application started
2020/08/27 16:14:42 [alert] 30#30 Python failed to import module "bikehub.wsgi"
Traceback (most recent call last):
  File "/code/bikehub/bikehub/wsgi.py", line 24, in <module>
    application = get_wsgi_application()
  File "/usr/local/lib/python3.7/dist-packages/django/core/wsgi.py", line 12, in get_wsgi_application
    django.setup(set_prefix=False)
  File "/usr/local/lib/python3.7/dist-packages/django/__init__.py", line 24, in setup
    apps.populate(settings.INSTALLED_APPS)
  File "/usr/local/lib/python3.7/dist-packages/django/apps/registry.py", line 91, in populate
    app_config = AppConfig.create(entry)
  File "/usr/local/lib/python3.7/dist-packages/django/apps/config.py", line 90, in create
    module = import_module(entry)
  File "/usr/lib/python3.7/importlib/__init__.py", line 127, in import_module
    return _bootstrap._gcd_import(name[level:], package, level)
ModuleNotFoundError: No module named 'corsheaders'
2020/08/27 16:14:43 [notice] 22#22 process 30 exited with code 1
2020/08/27 16:14:43 [warn] 26#26 failed to start application "django-app"
2020/08/27 16:14:43 [alert] 26#26 failed to apply new conf
2020/08/27 16:14:44 [info] 17#17 discovery started
2020/08/27 16:14:44 [notice] 17#17 module: python 3.7.3 "/usr/lib/unit/modules/python3.7.unit.so"
2020/08/27 16:14:44 [info] 1#1 controller started
2020/08/27 16:14:44 [notice] 1#1 process 17 exited with code 0
2020/08/27 16:14:44 [info] 19#19 router started
2020/08/27 16:14:44 [info] 19#19 OpenSSL 1.1.1d  10 Sep 2019, 1010104f
2020/08/27 16:15:55 [notice] 1#1 process 18 exited with code 0
2020/08/27 16:15:55 [notice] 1#1 process 19 exited with code 0
2020/08/27 16:20:25 [info] 20#20 discovery started
2020/08/27 16:20:25 [notice] 20#20 module: python 3.7.3 "/usr/lib/unit/modules/python3.7.unit.so"
2020/08/27 16:20:25 [info] 19#19 controller started
2020/08/27 16:20:25 [notice] 19#19 process 20 exited with code 0
2020/08/27 16:20:25 [info] 23#23 router started
2020/08/27 16:20:25 [info] 23#23 OpenSSL 1.1.1d  10 Sep 2019, 1010104f
2020/08/27 16:20:25 [info] 27#27 "django-app" application started
2020/08/27 16:20:25 [alert] 27#27 Python failed to import module "bikehub.wsgi"
Traceback (most recent call last):
  File "/code/bikehub/bikehub/wsgi.py", line 24, in <module>
    application = get_wsgi_application()
  File "/usr/local/lib/python3.7/dist-packages/django/core/wsgi.py", line 12, in get_wsgi_application
    django.setup(set_prefix=False)
  File "/usr/local/lib/python3.7/dist-packages/django/__init__.py", line 24, in setup
    apps.populate(settings.INSTALLED_APPS)
  File "/usr/local/lib/python3.7/dist-packages/django/apps/registry.py", line 91, in populate
    app_config = AppConfig.create(entry)
  File "/usr/local/lib/python3.7/dist-packages/django/apps/config.py", line 90, in create
    module = import_module(entry)
  File "/usr/lib/python3.7/importlib/__init__.py", line 127, in import_module
    return _bootstrap._gcd_import(name[level:], package, level)
ModuleNotFoundError: No module named 'corsheaders'
2020/08/27 16:20:26 [notice] 19#19 process 27 exited with code 1
2020/08/27 16:20:26 [warn] 23#23 failed to start application "django-app"
2020/08/27 16:20:26 [alert] 23#23 failed to apply new conf
2020/08/27 16:20:26 [info] 17#17 discovery started
2020/08/27 16:20:26 [notice] 17#17 module: python 3.7.3 "/usr/lib/unit/modules/python3.7.unit.so"
2020/08/27 16:20:26 [info] 1#1 controller started
2020/08/27 16:20:26 [notice] 1#1 process 17 exited with code 0
2020/08/27 16:20:26 [info] 19#19 router started
2020/08/27 16:20:26 [info] 19#19 OpenSSL 1.1.1d  10 Sep 2019, 1010104f
2020/08/27 16:22:00 [notice] 1#1 process 18 exited with code 0
2020/08/27 16:22:00 [notice] 1#1 process 19 exited with code 0
2020/08/27 16:22:09 [info] 26#26 discovery started
2020/08/27 16:22:09 [notice] 26#26 module: python 3.7.3 "/usr/lib/unit/modules/python3.7.unit.so"
2020/08/27 16:22:09 [info] 1#1 controller started
2020/08/27 16:22:09 [notice] 1#1 process 26 exited with code 0
2020/08/27 16:22:09 [info] 28#28 router started
2020/08/27 16:22:09 [info] 28#28 OpenSSL 1.1.1d  10 Sep 2019, 1010104f
2020/08/27 16:22:34 [notice] 1#1 process 27 exited with code 0
2020/08/27 16:22:34 [notice] 1#1 process 28 exited with code 0
2020/08/27 16:22:40 [info] 17#17 discovery started
2020/08/27 16:22:40 [notice] 17#17 module: python 3.7.3 "/usr/lib/unit/modules/python3.7.unit.so"
2020/08/27 16:22:40 [info] 1#1 controller started
2020/08/27 16:22:40 [notice] 1#1 process 17 exited with code 0
2020/08/27 16:22:40 [info] 19#19 router started
2020/08/27 16:22:40 [info] 19#19 OpenSSL 1.1.1d  10 Sep 2019, 1010104f
2020/08/27 16:22:55 [notice] 1#1 process 18 exited with code 0
2020/08/27 16:22:55 [notice] 1#1 process 19 exited with code 0
2020/08/27 16:25:21 [info] 20#20 discovery started
2020/08/27 16:25:21 [notice] 20#20 module: python 3.7.3 "/usr/lib/unit/modules/python3.7.unit.so"
2020/08/27 16:25:21 [info] 19#19 controller started
2020/08/27 16:25:21 [notice] 19#19 process 20 exited with code 0
2020/08/27 16:25:21 [info] 23#23 router started
2020/08/27 16:25:21 [info] 23#23 OpenSSL 1.1.1d  10 Sep 2019, 1010104f
2020/08/27 16:25:21 [info] 27#27 "django-app" application started
2020/08/27 16:25:22 [notice] 19#19 process 22 exited with code 0
2020/08/27 16:25:22 [notice] 19#19 process 23 exited with code 0
2020/08/27 16:25:22 [notice] 19#19 process 27 exited with code 0
2020/08/27 16:25:22 [info] 38#38 discovery started
2020/08/27 16:25:22 [notice] 38#38 module: python 3.7.3 "/usr/lib/unit/modules/python3.7.unit.so"
2020/08/27 16:25:22 [info] 1#1 controller started
2020/08/27 16:25:22 [notice] 1#1 process 38 exited with code 0
2020/08/27 16:25:22 [info] 40#40 router started
2020/08/27 16:25:22 [info] 40#40 OpenSSL 1.1.1d  10 Sep 2019, 1010104f
2020/08/27 16:25:22 [info] 41#41 "django-app" application started
2020/08/27 16:26:52 [notice] 1#1 process 39 exited with code 0
2020/08/27 16:26:52 [notice] 1#1 process 40 exited with code 0
2020/08/27 16:26:52 [notice] 1#1 process 41 exited with code 0
2020/08/27 17:01:37 [info] 21#21 discovery started
2020/08/27 17:01:37 [notice] 21#21 module: python 3.7.3 "/usr/lib/unit/modules/python3.7.unit.so"
2020/08/27 17:01:37 [info] 20#20 controller started
2020/08/27 17:01:37 [notice] 20#20 process 21 exited with code 0
2020/08/27 17:01:37 [info] 24#24 router started
2020/08/27 17:01:37 [info] 24#24 OpenSSL 1.1.1d  10 Sep 2019, 1010104f
2020/08/27 17:01:37 [info] 28#28 "django-app" application started
2020/08/27 17:01:38 [notice] 20#20 process 23 exited with code 0
2020/08/27 17:01:38 [notice] 20#20 process 24 exited with code 0
2020/08/27 17:01:38 [notice] 20#20 process 28 exited with code 0
2020/08/27 17:01:38 [info] 40#40 discovery started
2020/08/27 17:01:38 [notice] 40#40 module: python 3.7.3 "/usr/lib/unit/modules/python3.7.unit.so"
2020/08/27 17:01:38 [info] 1#1 controller started
2020/08/27 17:01:38 [notice] 1#1 process 40 exited with code 0
2020/08/27 17:01:38 [info] 42#42 router started
2020/08/27 17:01:38 [info] 42#42 OpenSSL 1.1.1d  10 Sep 2019, 1010104f
2020/08/27 17:01:38 [info] 43#43 "django-app" application started
Invalid HTTP_HOST header: 'example'. You may need to add 'example' to ALLOWED_HOSTS.
Bad Request: /
2020/08/27 17:04:12 [notice] 1#1 process 41 exited with code 0
2020/08/27 17:04:12 [notice] 1#1 process 42 exited with code 0
2020/08/27 17:04:12 [notice] 1#1 process 43 exited with code 0
2020/08/27 17:04:21 [info] 16#16 discovery started
2020/08/27 17:04:21 [notice] 16#16 module: python 3.7.3 "/usr/lib/unit/modules/python3.7.unit.so"
2020/08/27 17:04:21 [info] 1#1 controller started
2020/08/27 17:04:21 [notice] 1#1 process 16 exited with code 0
2020/08/27 17:04:21 [info] 18#18 router started
2020/08/27 17:04:21 [info] 18#18 OpenSSL 1.1.1d  10 Sep 2019, 1010104f
2020/08/27 17:04:21 [info] 19#19 "django-app" application started
2020/08/27 17:04:37 [notice] 1#1 process 17 exited with code 0
2020/08/27 17:04:38 [notice] 1#1 process 18 exited with code 0
2020/08/27 17:04:38 [notice] 1#1 process 19 exited with code 0
2020/08/27 17:04:56 [info] 17#17 discovery started
2020/08/27 17:04:56 [notice] 17#17 module: python 3.7.3 "/usr/lib/unit/modules/python3.7.unit.so"
2020/08/27 17:04:56 [info] 1#1 controller started
2020/08/27 17:04:56 [notice] 1#1 process 17 exited with code 0
2020/08/27 17:04:56 [info] 19#19 router started
2020/08/27 17:04:56 [info] 19#19 OpenSSL 1.1.1d  10 Sep 2019, 1010104f
2020/08/27 17:04:56 [info] 20#20 "django-app" application started
2020/08/27 17:05:27 [notice] 1#1 process 18 exited with code 0
2020/08/27 17:05:27 [notice] 1#1 process 19 exited with code 0
2020/08/27 17:05:27 [notice] 1#1 process 20 exited with code 0
2020/08/27 17:12:28 [info] 21#21 discovery started
2020/08/27 17:12:28 [notice] 21#21 module: python 3.7.3 "/usr/lib/unit/modules/python3.7.unit.so"
2020/08/27 17:12:28 [info] 20#20 controller started
2020/08/27 17:12:28 [notice] 20#20 process 21 exited with code 0
2020/08/27 17:12:28 [info] 24#24 router started
2020/08/27 17:12:28 [info] 24#24 OpenSSL 1.1.1d  10 Sep 2019, 1010104f
2020/08/27 17:12:28 [info] 28#28 "django-app" application started
2020/08/27 17:12:29 [notice] 20#20 process 23 exited with code 0
2020/08/27 17:12:29 [notice] 20#20 process 24 exited with code 0
2020/08/27 17:12:29 [notice] 20#20 process 28 exited with code 0
2020/08/27 17:12:29 [info] 39#39 discovery started
2020/08/27 17:12:29 [notice] 39#39 module: python 3.7.3 "/usr/lib/unit/modules/python3.7.unit.so"
2020/08/27 17:12:29 [info] 1#1 controller started
2020/08/27 17:12:29 [notice] 1#1 process 39 exited with code 0
2020/08/27 17:12:29 [info] 41#41 router started
2020/08/27 17:12:29 [info] 41#41 OpenSSL 1.1.1d  10 Sep 2019, 1010104f
2020/08/27 17:12:29 [info] 42#42 "django-app" application started
Not Found: /
Not Found: /favicon.ico
Internal Server Error: /admin/login/
Traceback (most recent call last):
  File "/usr/local/lib/python3.7/dist-packages/django/db/backends/utils.py", line 86, in _execute
    return self.cursor.execute(sql, params)
  File "/usr/local/lib/python3.7/dist-packages/django/db/backends/mysql/base.py", line 74, in execute
    return self.cursor.execute(query, args)
  File "/usr/local/lib/python3.7/dist-packages/MySQLdb/cursors.py", line 206, in execute
    res = self._query(query)
  File "/usr/local/lib/python3.7/dist-packages/MySQLdb/cursors.py", line 319, in _query
    db.query(q)
  File "/usr/local/lib/python3.7/dist-packages/MySQLdb/connections.py", line 259, in query
    _mysql.connection.query(self, query)
MySQLdb._exceptions.ProgrammingError: (1146, "Table 'django.django_site' doesn't exist")

The above exception was the direct cause of the following exception:

Traceback (most recent call last):
  File "/usr/local/lib/python3.7/dist-packages/django/core/handlers/exception.py", line 34, in inner
    response = get_response(request)
  File "/usr/local/lib/python3.7/dist-packages/django/core/handlers/base.py", line 115, in _get_response
    response = self.process_exception_by_middleware(e, request)
  File "/usr/local/lib/python3.7/dist-packages/django/core/handlers/base.py", line 113, in _get_response
    response = wrapped_callback(request, *callback_args, **callback_kwargs)
  File "/usr/local/lib/python3.7/dist-packages/django/views/decorators/cache.py", line 44, in _wrapped_view_func
    response = view_func(request, *args, **kwargs)
  File "/usr/local/lib/python3.7/dist-packages/django/contrib/admin/sites.py", line 407, in login
    return LoginView.as_view(**defaults)(request)
  File "/usr/local/lib/python3.7/dist-packages/django/views/generic/base.py", line 71, in view
    return self.dispatch(request, *args, **kwargs)
  File "/usr/local/lib/python3.7/dist-packages/django/utils/decorators.py", line 43, in _wrapper
    return bound_method(*args, **kwargs)
  File "/usr/local/lib/python3.7/dist-packages/django/views/decorators/debug.py", line 76, in sensitive_post_parameters_wrapper
    return view(request, *args, **kwargs)
  File "/usr/local/lib/python3.7/dist-packages/django/utils/decorators.py", line 43, in _wrapper
    return bound_method(*args, **kwargs)
  File "/usr/local/lib/python3.7/dist-packages/django/utils/decorators.py", line 130, in _wrapped_view
    response = view_func(request, *args, **kwargs)
  File "/usr/local/lib/python3.7/dist-packages/django/utils/decorators.py", line 43, in _wrapper
    return bound_method(*args, **kwargs)
  File "/usr/local/lib/python3.7/dist-packages/django/views/decorators/cache.py", line 44, in _wrapped_view_func
    response = view_func(request, *args, **kwargs)
  File "/usr/local/lib/python3.7/dist-packages/django/contrib/auth/views.py", line 63, in dispatch
    return super().dispatch(request, *args, **kwargs)
  File "/usr/local/lib/python3.7/dist-packages/django/views/generic/base.py", line 97, in dispatch
    return handler(request, *args, **kwargs)
  File "/usr/local/lib/python3.7/dist-packages/django/views/generic/edit.py", line 133, in get
    return self.render_to_response(self.get_context_data())
  File "/usr/local/lib/python3.7/dist-packages/django/contrib/auth/views.py", line 97, in get_context_data
    current_site = get_current_site(self.request)
  File "/usr/local/lib/python3.7/dist-packages/django/contrib/sites/shortcuts.py", line 13, in get_current_site
    return Site.objects.get_current(request)
  File "/usr/local/lib/python3.7/dist-packages/django/contrib/sites/models.py", line 58, in get_current
    return self._get_site_by_id(site_id)
  File "/usr/local/lib/python3.7/dist-packages/django/contrib/sites/models.py", line 30, in _get_site_by_id
    site = self.get(pk=site_id)
  File "/usr/local/lib/python3.7/dist-packages/django/db/models/manager.py", line 82, in manager_method
    return getattr(self.get_queryset(), name)(*args, **kwargs)
  File "/usr/local/lib/python3.7/dist-packages/django/db/models/query.py", line 411, in get
    num = len(clone)
  File "/usr/local/lib/python3.7/dist-packages/django/db/models/query.py", line 258, in __len__
    self._fetch_all()
  File "/usr/local/lib/python3.7/dist-packages/django/db/models/query.py", line 1261, in _fetch_all
    self._result_cache = list(self._iterable_class(self))
  File "/usr/local/lib/python3.7/dist-packages/django/db/models/query.py", line 57, in __iter__
    results = compiler.execute_sql(chunked_fetch=self.chunked_fetch, chunk_size=self.chunk_size)
  File "/usr/local/lib/python3.7/dist-packages/django/db/models/sql/compiler.py", line 1152, in execute_sql
    cursor.execute(sql, params)
  File "/usr/local/lib/python3.7/dist-packages/django/db/backends/utils.py", line 100, in execute
    return super().execute(sql, params)
  File "/usr/local/lib/python3.7/dist-packages/django/db/backends/utils.py", line 68, in execute
    return self._execute_with_wrappers(sql, params, many=False, executor=self._execute)
  File "/usr/local/lib/python3.7/dist-packages/django/db/backends/utils.py", line 77, in _execute_with_wrappers
    return executor(sql, params, many, context)
  File "/usr/local/lib/python3.7/dist-packages/django/db/backends/utils.py", line 86, in _execute
    return self.cursor.execute(sql, params)
  File "/usr/local/lib/python3.7/dist-packages/django/db/utils.py", line 90, in __exit__
    raise dj_exc_value.with_traceback(traceback) from exc_value
  File "/usr/local/lib/python3.7/dist-packages/django/db/backends/utils.py", line 86, in _execute
    return self.cursor.execute(sql, params)
  File "/usr/local/lib/python3.7/dist-packages/django/db/backends/mysql/base.py", line 74, in execute
    return self.cursor.execute(query, args)
  File "/usr/local/lib/python3.7/dist-packages/MySQLdb/cursors.py", line 206, in execute
    res = self._query(query)
  File "/usr/local/lib/python3.7/dist-packages/MySQLdb/cursors.py", line 319, in _query
    db.query(q)
  File "/usr/local/lib/python3.7/dist-packages/MySQLdb/connections.py", line 259, in query
    _mysql.connection.query(self, query)
django.db.utils.ProgrammingError: (1146, "Table 'django.django_site' doesn't exist")
Not Found: /
Not Found: /rest-auth/registaration
Method Not Allowed: /rest-auth/registration/
2020/08/27 17:16:43 [notice] 1#1 process 40 exited with code 0
2020/08/27 17:16:43 [notice] 1#1 process 41 exited with code 0
2020/08/27 17:16:43 [notice] 1#1 process 42 exited with code 0
2020/08/27 17:16:44 [info] 17#17 discovery started
2020/08/27 17:16:44 [notice] 17#17 module: python 3.7.3 "/usr/lib/unit/modules/python3.7.unit.so"
2020/08/27 17:16:44 [info] 1#1 controller started
2020/08/27 17:16:44 [notice] 1#1 process 17 exited with code 0
2020/08/27 17:16:44 [info] 19#19 router started
2020/08/27 17:16:44 [info] 19#19 OpenSSL 1.1.1d  10 Sep 2019, 1010104f
2020/08/27 17:16:44 [info] 20#20 "django-app" application started
Method Not Allowed: /rest-auth/registration/
Method Not Allowed: /rest-auth/registration/
Method Not Allowed: /rest-auth/registration/
Method Not Allowed: /rest-auth/registration/
Method Not Allowed: /rest-auth/registration/
Method Not Allowed: /rest-auth/registration/
Method Not Allowed: /rest-auth/registration/
Method Not Allowed: /rest-auth/registration/
Method Not Allowed: /rest-auth/registration/
Internal Server Error: /rest-auth/registration/
Traceback (most recent call last):
  File "/usr/local/lib/python3.7/dist-packages/django/db/backends/utils.py", line 86, in _execute
    return self.cursor.execute(sql, params)
  File "/usr/local/lib/python3.7/dist-packages/django/db/backends/mysql/base.py", line 74, in execute
    return self.cursor.execute(query, args)
  File "/usr/local/lib/python3.7/dist-packages/MySQLdb/cursors.py", line 206, in execute
    res = self._query(query)
  File "/usr/local/lib/python3.7/dist-packages/MySQLdb/cursors.py", line 319, in _query
    db.query(q)
  File "/usr/local/lib/python3.7/dist-packages/MySQLdb/connections.py", line 259, in query
    _mysql.connection.query(self, query)
MySQLdb._exceptions.IntegrityError: (1452, 'Cannot add or update a child row: a foreign key constraint fails (`django`.`account_emailaddress`, CONSTRAINT `account_emailaddress_user_id_2c513194_fk_users_user_id` FOREIGN KEY (`user_id`) REFERENCES `users` (`user_id`))')

The above exception was the direct cause of the following exception:

Traceback (most recent call last):
  File "/usr/local/lib/python3.7/dist-packages/django/core/handlers/exception.py", line 34, in inner
    response = get_response(request)
  File "/usr/local/lib/python3.7/dist-packages/django/core/handlers/base.py", line 115, in _get_response
    response = self.process_exception_by_middleware(e, request)
  File "/usr/local/lib/python3.7/dist-packages/django/core/handlers/base.py", line 113, in _get_response
    response = wrapped_callback(request, *callback_args, **callback_kwargs)
  File "/usr/local/lib/python3.7/dist-packages/django/views/decorators/csrf.py", line 54, in wrapped_view
    return view_func(*args, **kwargs)
  File "/usr/local/lib/python3.7/dist-packages/django/views/generic/base.py", line 71, in view
    return self.dispatch(request, *args, **kwargs)
  File "/usr/local/lib/python3.7/dist-packages/django/utils/decorators.py", line 43, in _wrapper
    return bound_method(*args, **kwargs)
  File "/usr/local/lib/python3.7/dist-packages/django/views/decorators/debug.py", line 76, in sensitive_post_parameters_wrapper
    return view(request, *args, **kwargs)
  File "/usr/local/lib/python3.7/dist-packages/dj_rest_auth/registration/views.py", line 43, in dispatch
    return super(RegisterView, self).dispatch(*args, **kwargs)
  File "/usr/local/lib/python3.7/dist-packages/rest_framework/views.py", line 505, in dispatch
    response = self.handle_exception(exc)
  File "/usr/local/lib/python3.7/dist-packages/rest_framework/views.py", line 465, in handle_exception
    self.raise_uncaught_exception(exc)
  File "/usr/local/lib/python3.7/dist-packages/rest_framework/views.py", line 476, in raise_uncaught_exception
    raise exc
  File "/usr/local/lib/python3.7/dist-packages/rest_framework/views.py", line 502, in dispatch
    response = handler(request, *args, **kwargs)
  File "/usr/local/lib/python3.7/dist-packages/rest_framework/generics.py", line 190, in post
    return self.create(request, *args, **kwargs)
  File "/usr/local/lib/python3.7/dist-packages/dj_rest_auth/registration/views.py", line 63, in create
    user = self.perform_create(serializer)
  File "/usr/local/lib/python3.7/dist-packages/dj_rest_auth/registration/views.py", line 71, in perform_create
    user = serializer.save(self.request)
  File "/usr/local/lib/python3.7/dist-packages/dj_rest_auth/registration/serializers.py", line 217, in save
    setup_user_email(request, user, [])
  File "/usr/local/lib/python3.7/dist-packages/allauth/account/utils.py", line 284, in setup_user_email
    a.save()
  File "/usr/local/lib/python3.7/dist-packages/django/db/models/base.py", line 746, in save
    force_update=force_update, update_fields=update_fields)
  File "/usr/local/lib/python3.7/dist-packages/django/db/models/base.py", line 784, in save_base
    force_update, using, update_fields,
  File "/usr/local/lib/python3.7/dist-packages/django/db/models/base.py", line 887, in _save_table
    results = self._do_insert(cls._base_manager, using, fields, returning_fields, raw)
  File "/usr/local/lib/python3.7/dist-packages/django/db/models/base.py", line 926, in _do_insert
    using=using, raw=raw,
  File "/usr/local/lib/python3.7/dist-packages/django/db/models/manager.py", line 82, in manager_method
    return getattr(self.get_queryset(), name)(*args, **kwargs)
  File "/usr/local/lib/python3.7/dist-packages/django/db/models/query.py", line 1204, in _insert
    return query.get_compiler(using=using).execute_sql(returning_fields)
  File "/usr/local/lib/python3.7/dist-packages/django/db/models/sql/compiler.py", line 1392, in execute_sql
    cursor.execute(sql, params)
  File "/usr/local/lib/python3.7/dist-packages/django/db/backends/utils.py", line 100, in execute
    return super().execute(sql, params)
  File "/usr/local/lib/python3.7/dist-packages/django/db/backends/utils.py", line 68, in execute
    return self._execute_with_wrappers(sql, params, many=False, executor=self._execute)
  File "/usr/local/lib/python3.7/dist-packages/django/db/backends/utils.py", line 77, in _execute_with_wrappers
    return executor(sql, params, many, context)
  File "/usr/local/lib/python3.7/dist-packages/django/db/backends/utils.py", line 86, in _execute
    return self.cursor.execute(sql, params)
  File "/usr/local/lib/python3.7/dist-packages/django/db/utils.py", line 90, in __exit__
    raise dj_exc_value.with_traceback(traceback) from exc_value
  File "/usr/local/lib/python3.7/dist-packages/django/db/backends/utils.py", line 86, in _execute
    return self.cursor.execute(sql, params)
  File "/usr/local/lib/python3.7/dist-packages/django/db/backends/mysql/base.py", line 74, in execute
    return self.cursor.execute(query, args)
  File "/usr/local/lib/python3.7/dist-packages/MySQLdb/cursors.py", line 206, in execute
    res = self._query(query)
  File "/usr/local/lib/python3.7/dist-packages/MySQLdb/cursors.py", line 319, in _query
    db.query(q)
  File "/usr/local/lib/python3.7/dist-packages/MySQLdb/connections.py", line 259, in query
    _mysql.connection.query(self, query)
django.db.utils.IntegrityError: (1452, 'Cannot add or update a child row: a foreign key constraint fails (`django`.`account_emailaddress`, CONSTRAINT `account_emailaddress_user_id_2c513194_fk_users_user_id` FOREIGN KEY (`user_id`) REFERENCES `users` (`user_id`))')
2020/08/27 17:20:22 [notice] 1#1 process 18 exited with code 0
2020/08/27 17:20:22 [notice] 1#1 process 19 exited with code 0
2020/08/27 17:20:22 [notice] 1#1 process 20 exited with code 0
2020/08/27 17:20:23 [info] 16#16 discovery started
2020/08/27 17:20:23 [notice] 16#16 module: python 3.7.3 "/usr/lib/unit/modules/python3.7.unit.so"
2020/08/27 17:20:23 [info] 1#1 controller started
2020/08/27 17:20:23 [notice] 1#1 process 16 exited with code 0
2020/08/27 17:20:23 [info] 18#18 router started
2020/08/27 17:20:23 [info] 18#18 OpenSSL 1.1.1d  10 Sep 2019, 1010104f
2020/08/27 17:20:23 [info] 19#19 "django-app" application started
Internal Server Error: /rest-auth/registration/
Traceback (most recent call last):
  File "/usr/local/lib/python3.7/dist-packages/django/core/handlers/exception.py", line 34, in inner
    response = get_response(request)
  File "/usr/local/lib/python3.7/dist-packages/django/core/handlers/base.py", line 115, in _get_response
    response = self.process_exception_by_middleware(e, request)
  File "/usr/local/lib/python3.7/dist-packages/django/core/handlers/base.py", line 113, in _get_response
    response = wrapped_callback(request, *callback_args, **callback_kwargs)
  File "/usr/local/lib/python3.7/dist-packages/django/views/decorators/csrf.py", line 54, in wrapped_view
    return view_func(*args, **kwargs)
  File "/usr/local/lib/python3.7/dist-packages/django/views/generic/base.py", line 71, in view
    return self.dispatch(request, *args, **kwargs)
  File "/usr/local/lib/python3.7/dist-packages/django/utils/decorators.py", line 43, in _wrapper
    return bound_method(*args, **kwargs)
  File "/usr/local/lib/python3.7/dist-packages/django/views/decorators/debug.py", line 76, in sensitive_post_parameters_wrapper
    return view(request, *args, **kwargs)
  File "/usr/local/lib/python3.7/dist-packages/dj_rest_auth/registration/views.py", line 43, in dispatch
    return super(RegisterView, self).dispatch(*args, **kwargs)
  File "/usr/local/lib/python3.7/dist-packages/rest_framework/views.py", line 505, in dispatch
    response = self.handle_exception(exc)
  File "/usr/local/lib/python3.7/dist-packages/rest_framework/views.py", line 465, in handle_exception
    self.raise_uncaught_exception(exc)
  File "/usr/local/lib/python3.7/dist-packages/rest_framework/views.py", line 476, in raise_uncaught_exception
    raise exc
  File "/usr/local/lib/python3.7/dist-packages/rest_framework/views.py", line 502, in dispatch
    response = handler(request, *args, **kwargs)
  File "/usr/local/lib/python3.7/dist-packages/rest_framework/generics.py", line 190, in post
    return self.create(request, *args, **kwargs)
  File "/usr/local/lib/python3.7/dist-packages/dj_rest_auth/registration/views.py", line 63, in create
    user = self.perform_create(serializer)
  File "/usr/local/lib/python3.7/dist-packages/dj_rest_auth/registration/views.py", line 81, in perform_create
    None)
  File "/usr/local/lib/python3.7/dist-packages/allauth/account/utils.py", line 192, in complete_signup
    signal_kwargs=signal_kwargs)
  File "/usr/local/lib/python3.7/dist-packages/allauth/account/utils.py", line 155, in perform_login
    send_email_confirmation(request, user, signup=signup)
  File "/usr/local/lib/python3.7/dist-packages/allauth/account/utils.py", line 323, in send_email_confirmation
    signup=signup)
  File "/usr/local/lib/python3.7/dist-packages/allauth/account/models.py", line 58, in send_confirmation
    confirmation.send(request, signup=signup)
  File "/usr/local/lib/python3.7/dist-packages/allauth/account/models.py", line 163, in send
    get_adapter(request).send_confirmation_mail(request, self, signup)
  File "/usr/local/lib/python3.7/dist-packages/allauth/account/adapter.py", line 455, in send_confirmation_mail
    ctx)
  File "/usr/local/lib/python3.7/dist-packages/allauth/account/adapter.py", line 137, in send_mail
    msg.send()
  File "/usr/local/lib/python3.7/dist-packages/django/core/mail/message.py", line 276, in send
    return self.get_connection(fail_silently).send_messages([self])
  File "/usr/local/lib/python3.7/dist-packages/django/core/mail/backends/smtp.py", line 102, in send_messages
    new_conn_created = self.open()
  File "/usr/local/lib/python3.7/dist-packages/django/core/mail/backends/smtp.py", line 62, in open
    self.connection = self.connection_class(self.host, self.port, **connection_params)
  File "/usr/lib/python3.7/smtplib.py", line 251, in __init__
    (code, msg) = self.connect(host, port)
  File "/usr/lib/python3.7/smtplib.py", line 336, in connect
    self.sock = self._get_socket(host, port, self.timeout)
  File "/usr/lib/python3.7/smtplib.py", line 307, in _get_socket
    self.source_address)
  File "/usr/lib/python3.7/socket.py", line 727, in create_connection
    raise err
  File "/usr/lib/python3.7/socket.py", line 716, in create_connection
    sock.connect(sa)
OSError: [Errno 99] Cannot assign requested address
Bad Request: /rest-auth/registration/
Internal Server Error: /rest-auth/registration/
Traceback (most recent call last):
  File "/usr/local/lib/python3.7/dist-packages/django/core/handlers/exception.py", line 34, in inner
    response = get_response(request)
  File "/usr/local/lib/python3.7/dist-packages/django/core/handlers/base.py", line 115, in _get_response
    response = self.process_exception_by_middleware(e, request)
  File "/usr/local/lib/python3.7/dist-packages/django/core/handlers/base.py", line 113, in _get_response
    response = wrapped_callback(request, *callback_args, **callback_kwargs)
  File "/usr/local/lib/python3.7/dist-packages/django/views/decorators/csrf.py", line 54, in wrapped_view
    return view_func(*args, **kwargs)
  File "/usr/local/lib/python3.7/dist-packages/django/views/generic/base.py", line 71, in view
    return self.dispatch(request, *args, **kwargs)
  File "/usr/local/lib/python3.7/dist-packages/django/utils/decorators.py", line 43, in _wrapper
    return bound_method(*args, **kwargs)
  File "/usr/local/lib/python3.7/dist-packages/django/views/decorators/debug.py", line 76, in sensitive_post_parameters_wrapper
    return view(request, *args, **kwargs)
  File "/usr/local/lib/python3.7/dist-packages/dj_rest_auth/registration/views.py", line 43, in dispatch
    return super(RegisterView, self).dispatch(*args, **kwargs)
  File "/usr/local/lib/python3.7/dist-packages/rest_framework/views.py", line 505, in dispatch
    response = self.handle_exception(exc)
  File "/usr/local/lib/python3.7/dist-packages/rest_framework/views.py", line 465, in handle_exception
    self.raise_uncaught_exception(exc)
  File "/usr/local/lib/python3.7/dist-packages/rest_framework/views.py", line 476, in raise_uncaught_exception
    raise exc
  File "/usr/local/lib/python3.7/dist-packages/rest_framework/views.py", line 502, in dispatch
    response = handler(request, *args, **kwargs)
  File "/usr/local/lib/python3.7/dist-packages/rest_framework/generics.py", line 190, in post
    return self.create(request, *args, **kwargs)
  File "/usr/local/lib/python3.7/dist-packages/dj_rest_auth/registration/views.py", line 63, in create
    user = self.perform_create(serializer)
  File "/usr/local/lib/python3.7/dist-packages/dj_rest_auth/registration/views.py", line 81, in perform_create
    None)
  File "/usr/local/lib/python3.7/dist-packages/allauth/account/utils.py", line 192, in complete_signup
    signal_kwargs=signal_kwargs)
  File "/usr/local/lib/python3.7/dist-packages/allauth/account/utils.py", line 155, in perform_login
    send_email_confirmation(request, user, signup=signup)
  File "/usr/local/lib/python3.7/dist-packages/allauth/account/utils.py", line 323, in send_email_confirmation
    signup=signup)
  File "/usr/local/lib/python3.7/dist-packages/allauth/account/models.py", line 58, in send_confirmation
    confirmation.send(request, signup=signup)
  File "/usr/local/lib/python3.7/dist-packages/allauth/account/models.py", line 163, in send
    get_adapter(request).send_confirmation_mail(request, self, signup)
  File "/usr/local/lib/python3.7/dist-packages/allauth/account/adapter.py", line 455, in send_confirmation_mail
    ctx)
  File "/usr/local/lib/python3.7/dist-packages/allauth/account/adapter.py", line 137, in send_mail
    msg.send()
  File "/usr/local/lib/python3.7/dist-packages/django/core/mail/message.py", line 276, in send
    return self.get_connection(fail_silently).send_messages([self])
  File "/usr/local/lib/python3.7/dist-packages/django/core/mail/backends/smtp.py", line 102, in send_messages
    new_conn_created = self.open()
  File "/usr/local/lib/python3.7/dist-packages/django/core/mail/backends/smtp.py", line 62, in open
    self.connection = self.connection_class(self.host, self.port, **connection_params)
  File "/usr/lib/python3.7/smtplib.py", line 251, in __init__
    (code, msg) = self.connect(host, port)
  File "/usr/lib/python3.7/smtplib.py", line 336, in connect
    self.sock = self._get_socket(host, port, self.timeout)
  File "/usr/lib/python3.7/smtplib.py", line 307, in _get_socket
    self.source_address)
  File "/usr/lib/python3.7/socket.py", line 727, in create_connection
    raise err
  File "/usr/lib/python3.7/socket.py", line 716, in create_connection
    sock.connect(sa)
OSError: [Errno 99] Cannot assign requested address
Bad Request: /rest-auth/registration/
Method Not Allowed: /rest-auth/login/
Internal Server Error: /rest-auth/login/
Traceback (most recent call last):
  File "/usr/local/lib/python3.7/dist-packages/django/core/handlers/exception.py", line 34, in inner
    response = get_response(request)
  File "/usr/local/lib/python3.7/dist-packages/django/core/handlers/base.py", line 115, in _get_response
    response = self.process_exception_by_middleware(e, request)
  File "/usr/local/lib/python3.7/dist-packages/django/core/handlers/base.py", line 113, in _get_response
    response = wrapped_callback(request, *callback_args, **callback_kwargs)
  File "/usr/local/lib/python3.7/dist-packages/django/views/decorators/csrf.py", line 54, in wrapped_view
    return view_func(*args, **kwargs)
  File "/usr/local/lib/python3.7/dist-packages/django/views/generic/base.py", line 71, in view
    return self.dispatch(request, *args, **kwargs)
  File "/usr/local/lib/python3.7/dist-packages/django/utils/decorators.py", line 43, in _wrapper
    return bound_method(*args, **kwargs)
  File "/usr/local/lib/python3.7/dist-packages/django/views/decorators/debug.py", line 76, in sensitive_post_parameters_wrapper
    return view(request, *args, **kwargs)
  File "/usr/local/lib/python3.7/dist-packages/dj_rest_auth/views.py", line 47, in dispatch
    return super(LoginView, self).dispatch(*args, **kwargs)
  File "/usr/local/lib/python3.7/dist-packages/rest_framework/views.py", line 505, in dispatch
    response = self.handle_exception(exc)
  File "/usr/local/lib/python3.7/dist-packages/rest_framework/views.py", line 465, in handle_exception
    self.raise_uncaught_exception(exc)
  File "/usr/local/lib/python3.7/dist-packages/rest_framework/views.py", line 476, in raise_uncaught_exception
    raise exc
  File "/usr/local/lib/python3.7/dist-packages/rest_framework/views.py", line 502, in dispatch
    response = handler(request, *args, **kwargs)
  File "/usr/local/lib/python3.7/dist-packages/dj_rest_auth/views.py", line 109, in post
    self.serializer.is_valid(raise_exception=True)
  File "/usr/local/lib/python3.7/dist-packages/rest_framework/serializers.py", line 234, in is_valid
    self._validated_data = self.run_validation(self.initial_data)
  File "/usr/local/lib/python3.7/dist-packages/rest_framework/serializers.py", line 436, in run_validation
    value = self.validate(value)
  File "/usr/local/lib/python3.7/dist-packages/dj_rest_auth/serializers.py", line 76, in validate
    user = self._validate_email(email, password)
  File "/usr/local/lib/python3.7/dist-packages/dj_rest_auth/serializers.py", line 33, in _validate_email
    user = self.authenticate(email=email, password=password)
  File "/usr/local/lib/python3.7/dist-packages/dj_rest_auth/serializers.py", line 27, in authenticate
    return authenticate(self.context['request'], **kwargs)
  File "/usr/local/lib/python3.7/dist-packages/django/contrib/auth/__init__.py", line 72, in authenticate
    user = backend.authenticate(request, **credentials)
  File "/usr/local/lib/python3.7/dist-packages/allauth/account/auth_backends.py", line 19, in authenticate
    ret = self._authenticate_by_email(**credentials)
  File "/usr/local/lib/python3.7/dist-packages/allauth/account/auth_backends.py", line 54, in _authenticate_by_email
    for user in filter_users_by_email(email):
  File "/usr/local/lib/python3.7/dist-packages/allauth/account/utils.py", line 399, in filter_users_by_email
    users.append(e.user)
  File "/usr/local/lib/python3.7/dist-packages/django/db/models/fields/related_descriptors.py", line 197, in __get__
    "%s has no %s." % (self.field.model.__name__, self.field.name)
allauth.account.models.EmailAddress.user.RelatedObjectDoesNotExist: EmailAddress has no user.
2020/08/27 17:23:38 [notice] 1#1 process 17 exited with code 0
2020/08/27 17:23:38 [notice] 1#1 process 18 exited with code 0
2020/08/27 17:23:38 [notice] 1#1 process 19 exited with code 0
2020/08/27 17:24:07 [info] 21#21 discovery started
2020/08/27 17:24:07 [notice] 21#21 module: python 3.7.3 "/usr/lib/unit/modules/python3.7.unit.so"
2020/08/27 17:24:07 [info] 19#19 controller started
2020/08/27 17:24:07 [notice] 19#19 process 21 exited with code 0
2020/08/27 17:24:07 [info] 23#23 router started
2020/08/27 17:24:07 [info] 23#23 OpenSSL 1.1.1d  10 Sep 2019, 1010104f
2020/08/27 17:24:07 [info] 27#27 "django-app" application started
2020/08/27 17:24:08 [notice] 19#19 process 22 exited with code 0
2020/08/27 17:24:08 [notice] 19#19 process 23 exited with code 0
2020/08/27 17:24:08 [notice] 19#19 process 27 exited with code 0
2020/08/27 17:24:08 [info] 39#39 discovery started
2020/08/27 17:24:08 [notice] 39#39 module: python 3.7.3 "/usr/lib/unit/modules/python3.7.unit.so"
2020/08/27 17:24:08 [info] 1#1 controller started
2020/08/27 17:24:08 [notice] 1#1 process 39 exited with code 0
2020/08/27 17:24:08 [info] 41#41 router started
2020/08/27 17:24:08 [info] 41#41 OpenSSL 1.1.1d  10 Sep 2019, 1010104f
2020/08/27 17:24:08 [info] 42#42 "django-app" application started
2020/08/27 17:26:09 [notice] 1#1 process 40 exited with code 0
2020/08/27 17:26:09 [notice] 1#1 process 41 exited with code 0
2020/08/27 17:26:09 [notice] 1#1 process 42 exited with code 0
2020/08/27 17:26:13 [info] 16#16 discovery started
2020/08/27 17:26:13 [notice] 16#16 module: python 3.7.3 "/usr/lib/unit/modules/python3.7.unit.so"
2020/08/27 17:26:13 [info] 1#1 controller started
2020/08/27 17:26:13 [notice] 1#1 process 16 exited with code 0
2020/08/27 17:26:13 [info] 18#18 router started
2020/08/27 17:26:13 [info] 18#18 OpenSSL 1.1.1d  10 Sep 2019, 1010104f
2020/08/27 17:26:13 [info] 19#19 "django-app" application started
Invalid HTTP_HOST header: 'localhost:8080'. You may need to add 'localhost' to ALLOWED_HOSTS.
Bad Request: /
Invalid HTTP_HOST header: 'localhost:8080'. You may need to add 'localhost' to ALLOWED_HOSTS.
Bad Request: /favicon.ico
2020/08/27 17:27:51 [notice] 1#1 process 17 exited with code 0
2020/08/27 17:27:51 [notice] 1#1 process 18 exited with code 0
2020/08/27 17:27:51 [notice] 1#1 process 19 exited with code 0
2020/08/27 17:27:57 [info] 16#16 discovery started
2020/08/27 17:27:57 [notice] 16#16 module: python 3.7.3 "/usr/lib/unit/modules/python3.7.unit.so"
2020/08/27 17:27:57 [info] 1#1 controller started
2020/08/27 17:27:57 [notice] 1#1 process 16 exited with code 0
2020/08/27 17:27:57 [info] 18#18 router started
2020/08/27 17:27:57 [info] 18#18 OpenSSL 1.1.1d  10 Sep 2019, 1010104f
2020/08/27 17:27:57 [info] 19#19 "django-app" application started
2020/08/27 17:31:00 [notice] 1#1 process 17 exited with code 0
2020/08/27 17:31:00 [notice] 1#1 process 18 exited with code 0
2020/08/27 17:31:00 [notice] 1#1 process 19 exited with code 0
2020/08/27 17:31:19 [info] 16#16 discovery started
2020/08/27 17:31:19 [notice] 16#16 module: python 3.7.3 "/usr/lib/unit/modules/python3.7.unit.so"
2020/08/27 17:31:19 [info] 1#1 controller started
2020/08/27 17:31:19 [notice] 1#1 process 16 exited with code 0
2020/08/27 17:31:19 [info] 18#18 router started
2020/08/27 17:31:19 [info] 18#18 OpenSSL 1.1.1d  10 Sep 2019, 1010104f
2020/08/27 17:31:19 [info] 19#19 "django-app" application started
Not Found: /
Not Found: /rest-auth
Method Not Allowed: /rest-auth/login/
Internal Server Error: /rest-auth/login/
Traceback (most recent call last):
  File "/usr/local/lib/python3.7/dist-packages/django/core/handlers/exception.py", line 34, in inner
    response = get_response(request)
  File "/usr/local/lib/python3.7/dist-packages/django/core/handlers/base.py", line 115, in _get_response
    response = self.process_exception_by_middleware(e, request)
  File "/usr/local/lib/python3.7/dist-packages/django/core/handlers/base.py", line 113, in _get_response
    response = wrapped_callback(request, *callback_args, **callback_kwargs)
  File "/usr/local/lib/python3.7/dist-packages/django/views/decorators/csrf.py", line 54, in wrapped_view
    return view_func(*args, **kwargs)
  File "/usr/local/lib/python3.7/dist-packages/django/views/generic/base.py", line 71, in view
    return self.dispatch(request, *args, **kwargs)
  File "/usr/local/lib/python3.7/dist-packages/django/utils/decorators.py", line 43, in _wrapper
    return bound_method(*args, **kwargs)
  File "/usr/local/lib/python3.7/dist-packages/django/views/decorators/debug.py", line 76, in sensitive_post_parameters_wrapper
    return view(request, *args, **kwargs)
  File "/usr/local/lib/python3.7/dist-packages/dj_rest_auth/views.py", line 47, in dispatch
    return super(LoginView, self).dispatch(*args, **kwargs)
  File "/usr/local/lib/python3.7/dist-packages/rest_framework/views.py", line 505, in dispatch
    response = self.handle_exception(exc)
  File "/usr/local/lib/python3.7/dist-packages/rest_framework/views.py", line 465, in handle_exception
    self.raise_uncaught_exception(exc)
  File "/usr/local/lib/python3.7/dist-packages/rest_framework/views.py", line 476, in raise_uncaught_exception
    raise exc
  File "/usr/local/lib/python3.7/dist-packages/rest_framework/views.py", line 502, in dispatch
    response = handler(request, *args, **kwargs)
  File "/usr/local/lib/python3.7/dist-packages/dj_rest_auth/views.py", line 111, in post
    self.login()
  File "/usr/local/lib/python3.7/dist-packages/dj_rest_auth/views.py", line 63, in login
    self.access_token, self.refresh_token = jwt_encode(self.user)
  File "/usr/local/lib/python3.7/dist-packages/dj_rest_auth/utils.py", line 30, in jwt_encode
    refresh = TOPS.get_token(user)
  File "/usr/local/lib/python3.7/dist-packages/rest_framework_simplejwt/serializers.py", line 68, in get_token
    return RefreshToken.for_user(user)
  File "/usr/local/lib/python3.7/dist-packages/rest_framework_simplejwt/tokens.py", line 161, in for_user
    user_id = getattr(user, api_settings.USER_ID_FIELD)
AttributeError: 'CustomUser' object has no attribute 'id'
2020/08/27 17:50:58 [info] 16#16 discovery started
2020/08/27 17:50:58 [notice] 16#16 module: python 3.7.3 "/usr/lib/unit/modules/python3.7.unit.so"
2020/08/27 17:50:58 [info] 1#1 controller started
2020/08/27 17:50:58 [notice] 1#1 process 16 exited with code 0
2020/08/27 17:50:58 [info] 18#18 router started
2020/08/27 17:50:58 [info] 18#18 OpenSSL 1.1.1d  10 Sep 2019, 1010104f
2020/08/27 17:50:58 [info] 19#19 "django-app" application started
Internal Server Error: /rest-auth/login/
Traceback (most recent call last):
  File "/usr/local/lib/python3.7/dist-packages/django/db/backends/utils.py", line 86, in _execute
    return self.cursor.execute(sql, params)
  File "/usr/local/lib/python3.7/dist-packages/django/db/backends/mysql/base.py", line 74, in execute
    return self.cursor.execute(query, args)
  File "/usr/local/lib/python3.7/dist-packages/MySQLdb/cursors.py", line 206, in execute
    res = self._query(query)
  File "/usr/local/lib/python3.7/dist-packages/MySQLdb/cursors.py", line 319, in _query
    db.query(q)
  File "/usr/local/lib/python3.7/dist-packages/MySQLdb/connections.py", line 259, in query
    _mysql.connection.query(self, query)
MySQLdb._exceptions.OperationalError: (1054, "Unknown column 'users.user_id' in 'field list'")

The above exception was the direct cause of the following exception:

Traceback (most recent call last):
  File "/usr/local/lib/python3.7/dist-packages/django/core/handlers/exception.py", line 34, in inner
    response = get_response(request)
  File "/usr/local/lib/python3.7/dist-packages/django/core/handlers/base.py", line 115, in _get_response
    response = self.process_exception_by_middleware(e, request)
  File "/usr/local/lib/python3.7/dist-packages/django/core/handlers/base.py", line 113, in _get_response
    response = wrapped_callback(request, *callback_args, **callback_kwargs)
  File "/usr/local/lib/python3.7/dist-packages/django/views/decorators/csrf.py", line 54, in wrapped_view
    return view_func(*args, **kwargs)
  File "/usr/local/lib/python3.7/dist-packages/django/views/generic/base.py", line 71, in view
    return self.dispatch(request, *args, **kwargs)
  File "/usr/local/lib/python3.7/dist-packages/django/utils/decorators.py", line 43, in _wrapper
    return bound_method(*args, **kwargs)
  File "/usr/local/lib/python3.7/dist-packages/django/views/decorators/debug.py", line 76, in sensitive_post_parameters_wrapper
    return view(request, *args, **kwargs)
  File "/usr/local/lib/python3.7/dist-packages/dj_rest_auth/views.py", line 47, in dispatch
    return super(LoginView, self).dispatch(*args, **kwargs)
  File "/usr/local/lib/python3.7/dist-packages/rest_framework/views.py", line 505, in dispatch
    response = self.handle_exception(exc)
  File "/usr/local/lib/python3.7/dist-packages/rest_framework/views.py", line 465, in handle_exception
    self.raise_uncaught_exception(exc)
  File "/usr/local/lib/python3.7/dist-packages/rest_framework/views.py", line 476, in raise_uncaught_exception
    raise exc
  File "/usr/local/lib/python3.7/dist-packages/rest_framework/views.py", line 493, in dispatch
    self.initial(request, *args, **kwargs)
  File "/usr/local/lib/python3.7/dist-packages/rest_framework/views.py", line 410, in initial
    self.perform_authentication(request)
  File "/usr/local/lib/python3.7/dist-packages/rest_framework/views.py", line 324, in perform_authentication
    request.user
  File "/usr/local/lib/python3.7/dist-packages/rest_framework/request.py", line 220, in user
    self._authenticate()
  File "/usr/local/lib/python3.7/dist-packages/rest_framework/request.py", line 373, in _authenticate
    user_auth_tuple = authenticator.authenticate(self)
  File "/usr/local/lib/python3.7/dist-packages/rest_framework/authentication.py", line 123, in authenticate
    if not user or not user.is_active:
  File "/usr/local/lib/python3.7/dist-packages/django/utils/functional.py", line 224, in inner
    self._setup()
  File "/usr/local/lib/python3.7/dist-packages/django/utils/functional.py", line 360, in _setup
    self._wrapped = self._setupfunc()
  File "/usr/local/lib/python3.7/dist-packages/django/contrib/auth/middleware.py", line 24, in <lambda>
    request.user = SimpleLazyObject(lambda: get_user(request))
  File "/usr/local/lib/python3.7/dist-packages/django/contrib/auth/middleware.py", line 12, in get_user
    request._cached_user = auth.get_user(request)
  File "/usr/local/lib/python3.7/dist-packages/django/contrib/auth/__init__.py", line 180, in get_user
    user = backend.get_user(user_id)
  File "/usr/local/lib/python3.7/dist-packages/django/contrib/auth/backends.py", line 161, in get_user
    user = UserModel._default_manager.get(pk=user_id)
  File "/usr/local/lib/python3.7/dist-packages/django/db/models/manager.py", line 82, in manager_method
    return getattr(self.get_queryset(), name)(*args, **kwargs)
  File "/usr/local/lib/python3.7/dist-packages/django/db/models/query.py", line 411, in get
    num = len(clone)
  File "/usr/local/lib/python3.7/dist-packages/django/db/models/query.py", line 258, in __len__
    self._fetch_all()
  File "/usr/local/lib/python3.7/dist-packages/django/db/models/query.py", line 1261, in _fetch_all
    self._result_cache = list(self._iterable_class(self))
  File "/usr/local/lib/python3.7/dist-packages/django/db/models/query.py", line 57, in __iter__
    results = compiler.execute_sql(chunked_fetch=self.chunked_fetch, chunk_size=self.chunk_size)
  File "/usr/local/lib/python3.7/dist-packages/django/db/models/sql/compiler.py", line 1152, in execute_sql
    cursor.execute(sql, params)
  File "/usr/local/lib/python3.7/dist-packages/django/db/backends/utils.py", line 100, in execute
    return super().execute(sql, params)
  File "/usr/local/lib/python3.7/dist-packages/django/db/backends/utils.py", line 68, in execute
    return self._execute_with_wrappers(sql, params, many=False, executor=self._execute)
  File "/usr/local/lib/python3.7/dist-packages/django/db/backends/utils.py", line 77, in _execute_with_wrappers
    return executor(sql, params, many, context)
  File "/usr/local/lib/python3.7/dist-packages/django/db/backends/utils.py", line 86, in _execute
    return self.cursor.execute(sql, params)
  File "/usr/local/lib/python3.7/dist-packages/django/db/utils.py", line 90, in __exit__
    raise dj_exc_value.with_traceback(traceback) from exc_value
  File "/usr/local/lib/python3.7/dist-packages/django/db/backends/utils.py", line 86, in _execute
    return self.cursor.execute(sql, params)
  File "/usr/local/lib/python3.7/dist-packages/django/db/backends/mysql/base.py", line 74, in execute
    return self.cursor.execute(query, args)
  File "/usr/local/lib/python3.7/dist-packages/MySQLdb/cursors.py", line 206, in execute
    res = self._query(query)
  File "/usr/local/lib/python3.7/dist-packages/MySQLdb/cursors.py", line 319, in _query
    db.query(q)
  File "/usr/local/lib/python3.7/dist-packages/MySQLdb/connections.py", line 259, in query
    _mysql.connection.query(self, query)
django.db.utils.OperationalError: (1054, "Unknown column 'users.user_id' in 'field list'")
2020/08/27 17:53:32 [notice] 1#1 process 17 exited with code 0
2020/08/27 17:53:32 [notice] 1#1 process 18 exited with code 0
2020/08/27 17:53:32 [notice] 1#1 process 19 exited with code 0
2020/08/27 17:53:33 [info] 16#16 discovery started
2020/08/27 17:53:33 [notice] 16#16 module: python 3.7.3 "/usr/lib/unit/modules/python3.7.unit.so"
2020/08/27 17:53:33 [info] 1#1 controller started
2020/08/27 17:53:33 [notice] 1#1 process 16 exited with code 0
2020/08/27 17:53:33 [info] 18#18 router started
2020/08/27 17:53:33 [info] 18#18 OpenSSL 1.1.1d  10 Sep 2019, 1010104f
2020/08/27 17:53:33 [info] 19#19 "django-app" application started
2020/08/27 21:03:30 [info] 21#21 discovery started
2020/08/27 21:03:30 [notice] 21#21 module: python 3.7.3 "/usr/lib/unit/modules/python3.7.unit.so"
2020/08/27 21:03:30 [info] 20#20 controller started
2020/08/27 21:03:30 [notice] 20#20 process 21 exited with code 0
2020/08/27 21:03:30 [info] 24#24 router started
2020/08/27 21:03:30 [info] 24#24 OpenSSL 1.1.1d  10 Sep 2019, 1010104f
2020/08/27 21:03:30 [info] 28#28 "django-app" application started
2020/08/27 21:03:32 [notice] 20#20 process 23 exited with code 0
2020/08/27 21:03:32 [notice] 20#20 process 24 exited with code 0
2020/08/27 21:03:32 [notice] 20#20 process 28 exited with code 0
2020/08/27 21:03:32 [info] 39#39 discovery started
2020/08/27 21:03:32 [notice] 39#39 module: python 3.7.3 "/usr/lib/unit/modules/python3.7.unit.so"
2020/08/27 21:03:32 [info] 1#1 controller started
2020/08/27 21:03:32 [notice] 1#1 process 39 exited with code 0
2020/08/27 21:03:32 [info] 41#41 router started
2020/08/27 21:03:32 [info] 41#41 OpenSSL 1.1.1d  10 Sep 2019, 1010104f
2020/08/27 21:03:32 [info] 42#42 "django-app" application started
Not Found: /
Not Found: /favicon.ico
Not Found: /rest-auth/registrasion
Method Not Allowed: /rest-auth/registration/
Internal Server Error: /rest-auth/registration/
Traceback (most recent call last):
  File "/usr/local/lib/python3.7/dist-packages/django/core/handlers/exception.py", line 34, in inner
    response = get_response(request)
  File "/usr/local/lib/python3.7/dist-packages/django/core/handlers/base.py", line 115, in _get_response
    response = self.process_exception_by_middleware(e, request)
  File "/usr/local/lib/python3.7/dist-packages/django/core/handlers/base.py", line 113, in _get_response
    response = wrapped_callback(request, *callback_args, **callback_kwargs)
  File "/usr/local/lib/python3.7/dist-packages/django/views/decorators/csrf.py", line 54, in wrapped_view
    return view_func(*args, **kwargs)
  File "/usr/local/lib/python3.7/dist-packages/django/views/generic/base.py", line 71, in view
    return self.dispatch(request, *args, **kwargs)
  File "/usr/local/lib/python3.7/dist-packages/django/utils/decorators.py", line 43, in _wrapper
    return bound_method(*args, **kwargs)
  File "/usr/local/lib/python3.7/dist-packages/django/views/decorators/debug.py", line 76, in sensitive_post_parameters_wrapper
    return view(request, *args, **kwargs)
  File "/usr/local/lib/python3.7/dist-packages/dj_rest_auth/registration/views.py", line 43, in dispatch
    return super(RegisterView, self).dispatch(*args, **kwargs)
  File "/usr/local/lib/python3.7/dist-packages/rest_framework/views.py", line 505, in dispatch
    response = self.handle_exception(exc)
  File "/usr/local/lib/python3.7/dist-packages/rest_framework/views.py", line 465, in handle_exception
    self.raise_uncaught_exception(exc)
  File "/usr/local/lib/python3.7/dist-packages/rest_framework/views.py", line 476, in raise_uncaught_exception
    raise exc
  File "/usr/local/lib/python3.7/dist-packages/rest_framework/views.py", line 502, in dispatch
    response = handler(request, *args, **kwargs)
  File "/usr/local/lib/python3.7/dist-packages/rest_framework/generics.py", line 190, in post
    return self.create(request, *args, **kwargs)
  File "/usr/local/lib/python3.7/dist-packages/dj_rest_auth/registration/views.py", line 63, in create
    user = self.perform_create(serializer)
  File "/usr/local/lib/python3.7/dist-packages/dj_rest_auth/registration/views.py", line 81, in perform_create
    None)
  File "/usr/local/lib/python3.7/dist-packages/allauth/account/utils.py", line 192, in complete_signup
    signal_kwargs=signal_kwargs)
  File "/usr/local/lib/python3.7/dist-packages/allauth/account/utils.py", line 155, in perform_login
    send_email_confirmation(request, user, signup=signup)
  File "/usr/local/lib/python3.7/dist-packages/allauth/account/utils.py", line 323, in send_email_confirmation
    signup=signup)
  File "/usr/local/lib/python3.7/dist-packages/allauth/account/models.py", line 58, in send_confirmation
    confirmation.send(request, signup=signup)
  File "/usr/local/lib/python3.7/dist-packages/allauth/account/models.py", line 163, in send
    get_adapter(request).send_confirmation_mail(request, self, signup)
  File "/usr/local/lib/python3.7/dist-packages/allauth/account/adapter.py", line 455, in send_confirmation_mail
    ctx)
  File "/usr/local/lib/python3.7/dist-packages/allauth/account/adapter.py", line 137, in send_mail
    msg.send()
  File "/usr/local/lib/python3.7/dist-packages/django/core/mail/message.py", line 276, in send
    return self.get_connection(fail_silently).send_messages([self])
  File "/usr/local/lib/python3.7/dist-packages/django/core/mail/backends/smtp.py", line 102, in send_messages
    new_conn_created = self.open()
  File "/usr/local/lib/python3.7/dist-packages/django/core/mail/backends/smtp.py", line 62, in open
    self.connection = self.connection_class(self.host, self.port, **connection_params)
  File "/usr/lib/python3.7/smtplib.py", line 251, in __init__
    (code, msg) = self.connect(host, port)
  File "/usr/lib/python3.7/smtplib.py", line 336, in connect
    self.sock = self._get_socket(host, port, self.timeout)
  File "/usr/lib/python3.7/smtplib.py", line 307, in _get_socket
    self.source_address)
  File "/usr/lib/python3.7/socket.py", line 727, in create_connection
    raise err
  File "/usr/lib/python3.7/socket.py", line 716, in create_connection
    sock.connect(sa)
OSError: [Errno 99] Cannot assign requested address
2020/08/27 21:18:25 [notice] 1#1 process 40 exited with code 0
2020/08/27 21:18:25 [notice] 1#1 process 41 exited with code 0
2020/08/27 21:18:25 [notice] 1#1 process 42 exited with code 0
2020/08/27 21:18:32 [info] 21#21 discovery started
2020/08/27 21:18:32 [notice] 21#21 module: python 3.7.3 "/usr/lib/unit/modules/python3.7.unit.so"
2020/08/27 21:18:32 [info] 19#19 controller started
2020/08/27 21:18:32 [info] 23#23 router started
2020/08/27 21:18:32 [notice] 19#19 process 21 exited with code 0
2020/08/27 21:18:32 [info] 23#23 OpenSSL 1.1.1d  10 Sep 2019, 1010104f
2020/08/27 21:18:32 [info] 27#27 "django-app" application started
2020/08/27 21:18:34 [notice] 19#19 process 22 exited with code 0
2020/08/27 21:18:34 [notice] 19#19 process 23 exited with code 0
2020/08/27 21:18:34 [notice] 19#19 process 27 exited with code 0
2020/08/27 21:18:34 [info] 39#39 discovery started
2020/08/27 21:18:34 [notice] 39#39 module: python 3.7.3 "/usr/lib/unit/modules/python3.7.unit.so"
2020/08/27 21:18:34 [info] 1#1 controller started
2020/08/27 21:18:34 [notice] 1#1 process 39 exited with code 0
2020/08/27 21:18:34 [info] 41#41 router started
2020/08/27 21:18:34 [info] 41#41 OpenSSL 1.1.1d  10 Sep 2019, 1010104f
2020/08/27 21:18:34 [info] 42#42 "django-app" application started
Bad Request: /rest-auth/registration/
Not Found: /favicon.ico
Internal Server Error: /rest-auth/registration/
Traceback (most recent call last):
  File "/usr/local/lib/python3.7/dist-packages/django/core/handlers/exception.py", line 34, in inner
    response = get_response(request)
  File "/usr/local/lib/python3.7/dist-packages/django/core/handlers/base.py", line 115, in _get_response
    response = self.process_exception_by_middleware(e, request)
  File "/usr/local/lib/python3.7/dist-packages/django/core/handlers/base.py", line 113, in _get_response
    response = wrapped_callback(request, *callback_args, **callback_kwargs)
  File "/usr/local/lib/python3.7/dist-packages/django/views/decorators/csrf.py", line 54, in wrapped_view
    return view_func(*args, **kwargs)
  File "/usr/local/lib/python3.7/dist-packages/django/views/generic/base.py", line 71, in view
    return self.dispatch(request, *args, **kwargs)
  File "/usr/local/lib/python3.7/dist-packages/django/utils/decorators.py", line 43, in _wrapper
    return bound_method(*args, **kwargs)
  File "/usr/local/lib/python3.7/dist-packages/django/views/decorators/debug.py", line 76, in sensitive_post_parameters_wrapper
    return view(request, *args, **kwargs)
  File "/usr/local/lib/python3.7/dist-packages/dj_rest_auth/registration/views.py", line 43, in dispatch
    return super(RegisterView, self).dispatch(*args, **kwargs)
  File "/usr/local/lib/python3.7/dist-packages/rest_framework/views.py", line 505, in dispatch
    response = self.handle_exception(exc)
  File "/usr/local/lib/python3.7/dist-packages/rest_framework/views.py", line 465, in handle_exception
    self.raise_uncaught_exception(exc)
  File "/usr/local/lib/python3.7/dist-packages/rest_framework/views.py", line 476, in raise_uncaught_exception
    raise exc
  File "/usr/local/lib/python3.7/dist-packages/rest_framework/views.py", line 502, in dispatch
    response = handler(request, *args, **kwargs)
  File "/usr/local/lib/python3.7/dist-packages/rest_framework/generics.py", line 190, in post
    return self.create(request, *args, **kwargs)
  File "/usr/local/lib/python3.7/dist-packages/dj_rest_auth/registration/views.py", line 63, in create
    user = self.perform_create(serializer)
  File "/usr/local/lib/python3.7/dist-packages/dj_rest_auth/registration/views.py", line 81, in perform_create
    None)
  File "/usr/local/lib/python3.7/dist-packages/allauth/account/utils.py", line 192, in complete_signup
    signal_kwargs=signal_kwargs)
  File "/usr/local/lib/python3.7/dist-packages/allauth/account/utils.py", line 157, in perform_login
    request, user)
  File "/usr/local/lib/python3.7/dist-packages/allauth/account/adapter.py", line 463, in respond_email_verification_sent
    reverse('account_email_verification_sent'))
  File "/usr/local/lib/python3.7/dist-packages/django/urls/base.py", line 87, in reverse
    return iri_to_uri(resolver._reverse_with_prefix(view, prefix, *args, **kwargs))
  File "/usr/local/lib/python3.7/dist-packages/django/urls/resolvers.py", line 677, in _reverse_with_prefix
    raise NoReverseMatch(msg)
django.urls.exceptions.NoReverseMatch: Reverse for 'account_email_verification_sent' not found. 'account_email_verification_sent' is not a valid view function or pattern name.
2020/08/27 21:22:56 [notice] 1#1 process 40 exited with code 0
2020/08/27 21:22:56 [notice] 1#1 process 41 exited with code 0
2020/08/27 21:22:56 [notice] 1#1 process 42 exited with code 0
2020/08/27 21:23:05 [info] 20#20 discovery started
2020/08/27 21:23:05 [notice] 20#20 module: python 3.7.3 "/usr/lib/unit/modules/python3.7.unit.so"
2020/08/27 21:23:05 [info] 19#19 controller started
2020/08/27 21:23:05 [notice] 19#19 process 20 exited with code 0
2020/08/27 21:23:05 [info] 23#23 router started
2020/08/27 21:23:05 [info] 23#23 OpenSSL 1.1.1d  10 Sep 2019, 1010104f
2020/08/27 21:23:05 [info] 27#27 "django-app" application started
2020/08/27 21:23:06 [notice] 19#19 process 22 exited with code 0
2020/08/27 21:23:06 [notice] 19#19 process 23 exited with code 0
Bad Request: /rest-auth/registration/
2020/08/27 21:23:07 [warn] 27#27 [unit] sendmsg(9, 468) failed: Broken pipe (32)
2020/08/27 21:23:07 [notice] 19#19 process 27 exited with code 0
2020/08/27 21:23:07 [info] 49#49 discovery started
2020/08/27 21:23:07 [notice] 49#49 module: python 3.7.3 "/usr/lib/unit/modules/python3.7.unit.so"
2020/08/27 21:23:07 [info] 1#1 controller started
2020/08/27 21:23:07 [notice] 1#1 process 49 exited with code 0
2020/08/27 21:23:07 [info] 51#51 router started
2020/08/27 21:23:07 [info] 51#51 OpenSSL 1.1.1d  10 Sep 2019, 1010104f
2020/08/27 21:23:07 [info] 52#52 "django-app" application started
Bad Request: /rest-auth/registration/
Not Found: /favicon.ico
Method Not Allowed: /rest-auth/login/
Internal Server Error: /rest-auth/login/
Traceback (most recent call last):
  File "/usr/local/lib/python3.7/dist-packages/django/core/handlers/exception.py", line 34, in inner
    response = get_response(request)
  File "/usr/local/lib/python3.7/dist-packages/django/core/handlers/base.py", line 115, in _get_response
    response = self.process_exception_by_middleware(e, request)
  File "/usr/local/lib/python3.7/dist-packages/django/core/handlers/base.py", line 113, in _get_response
    response = wrapped_callback(request, *callback_args, **callback_kwargs)
  File "/usr/local/lib/python3.7/dist-packages/django/views/decorators/csrf.py", line 54, in wrapped_view
    return view_func(*args, **kwargs)
  File "/usr/local/lib/python3.7/dist-packages/django/views/generic/base.py", line 71, in view
    return self.dispatch(request, *args, **kwargs)
  File "/usr/local/lib/python3.7/dist-packages/django/utils/decorators.py", line 43, in _wrapper
    return bound_method(*args, **kwargs)
  File "/usr/local/lib/python3.7/dist-packages/django/views/decorators/debug.py", line 76, in sensitive_post_parameters_wrapper
    return view(request, *args, **kwargs)
  File "/usr/local/lib/python3.7/dist-packages/dj_rest_auth/views.py", line 47, in dispatch
    return super(LoginView, self).dispatch(*args, **kwargs)
  File "/usr/local/lib/python3.7/dist-packages/rest_framework/views.py", line 505, in dispatch
    response = self.handle_exception(exc)
  File "/usr/local/lib/python3.7/dist-packages/rest_framework/views.py", line 465, in handle_exception
    self.raise_uncaught_exception(exc)
  File "/usr/local/lib/python3.7/dist-packages/rest_framework/views.py", line 476, in raise_uncaught_exception
    raise exc
  File "/usr/local/lib/python3.7/dist-packages/rest_framework/views.py", line 502, in dispatch
    response = handler(request, *args, **kwargs)
  File "/usr/local/lib/python3.7/dist-packages/dj_rest_auth/views.py", line 109, in post
    self.serializer.is_valid(raise_exception=True)
  File "/usr/local/lib/python3.7/dist-packages/rest_framework/serializers.py", line 234, in is_valid
    self._validated_data = self.run_validation(self.initial_data)
  File "/usr/local/lib/python3.7/dist-packages/rest_framework/serializers.py", line 436, in run_validation
    value = self.validate(value)
  File "/usr/local/lib/python3.7/dist-packages/dj_rest_auth/serializers.py", line 110, in validate
    email_address = user.emailaddress_set.get(email=user.email)
  File "/usr/local/lib/python3.7/dist-packages/django/db/models/manager.py", line 82, in manager_method
    return getattr(self.get_queryset(), name)(*args, **kwargs)
  File "/usr/local/lib/python3.7/dist-packages/django/db/models/query.py", line 417, in get
    self.model._meta.object_name
allauth.account.models.EmailAddress.DoesNotExist: EmailAddress matching query does not exist.
Internal Server Error: /rest-auth/login/
Traceback (most recent call last):
  File "/usr/local/lib/python3.7/dist-packages/django/core/handlers/exception.py", line 34, in inner
    response = get_response(request)
  File "/usr/local/lib/python3.7/dist-packages/django/core/handlers/base.py", line 115, in _get_response
    response = self.process_exception_by_middleware(e, request)
  File "/usr/local/lib/python3.7/dist-packages/django/core/handlers/base.py", line 113, in _get_response
    response = wrapped_callback(request, *callback_args, **callback_kwargs)
  File "/usr/local/lib/python3.7/dist-packages/django/views/decorators/csrf.py", line 54, in wrapped_view
    return view_func(*args, **kwargs)
  File "/usr/local/lib/python3.7/dist-packages/django/views/generic/base.py", line 71, in view
    return self.dispatch(request, *args, **kwargs)
  File "/usr/local/lib/python3.7/dist-packages/django/utils/decorators.py", line 43, in _wrapper
    return bound_method(*args, **kwargs)
  File "/usr/local/lib/python3.7/dist-packages/django/views/decorators/debug.py", line 76, in sensitive_post_parameters_wrapper
    return view(request, *args, **kwargs)
  File "/usr/local/lib/python3.7/dist-packages/dj_rest_auth/views.py", line 47, in dispatch
    return super(LoginView, self).dispatch(*args, **kwargs)
  File "/usr/local/lib/python3.7/dist-packages/rest_framework/views.py", line 505, in dispatch
    response = self.handle_exception(exc)
  File "/usr/local/lib/python3.7/dist-packages/rest_framework/views.py", line 465, in handle_exception
    self.raise_uncaught_exception(exc)
  File "/usr/local/lib/python3.7/dist-packages/rest_framework/views.py", line 476, in raise_uncaught_exception
    raise exc
  File "/usr/local/lib/python3.7/dist-packages/rest_framework/views.py", line 502, in dispatch
    response = handler(request, *args, **kwargs)
  File "/usr/local/lib/python3.7/dist-packages/dj_rest_auth/views.py", line 109, in post
    self.serializer.is_valid(raise_exception=True)
  File "/usr/local/lib/python3.7/dist-packages/rest_framework/serializers.py", line 234, in is_valid
    self._validated_data = self.run_validation(self.initial_data)
  File "/usr/local/lib/python3.7/dist-packages/rest_framework/serializers.py", line 436, in run_validation
    value = self.validate(value)
  File "/usr/local/lib/python3.7/dist-packages/dj_rest_auth/serializers.py", line 110, in validate
    email_address = user.emailaddress_set.get(email=user.email)
  File "/usr/local/lib/python3.7/dist-packages/django/db/models/manager.py", line 82, in manager_method
    return getattr(self.get_queryset(), name)(*args, **kwargs)
  File "/usr/local/lib/python3.7/dist-packages/django/db/models/query.py", line 417, in get
    self.model._meta.object_name
allauth.account.models.EmailAddress.DoesNotExist: EmailAddress matching query does not exist.
Method Not Allowed: /rest-auth/login/
Bad Request: /rest-auth/login/
Internal Server Error: /rest-auth/login/
Traceback (most recent call last):
  File "/usr/local/lib/python3.7/dist-packages/django/core/handlers/exception.py", line 34, in inner
    response = get_response(request)
  File "/usr/local/lib/python3.7/dist-packages/django/core/handlers/base.py", line 115, in _get_response
    response = self.process_exception_by_middleware(e, request)
  File "/usr/local/lib/python3.7/dist-packages/django/core/handlers/base.py", line 113, in _get_response
    response = wrapped_callback(request, *callback_args, **callback_kwargs)
  File "/usr/local/lib/python3.7/dist-packages/django/views/decorators/csrf.py", line 54, in wrapped_view
    return view_func(*args, **kwargs)
  File "/usr/local/lib/python3.7/dist-packages/django/views/generic/base.py", line 71, in view
    return self.dispatch(request, *args, **kwargs)
  File "/usr/local/lib/python3.7/dist-packages/django/utils/decorators.py", line 43, in _wrapper
    return bound_method(*args, **kwargs)
  File "/usr/local/lib/python3.7/dist-packages/django/views/decorators/debug.py", line 76, in sensitive_post_parameters_wrapper
    return view(request, *args, **kwargs)
  File "/usr/local/lib/python3.7/dist-packages/dj_rest_auth/views.py", line 47, in dispatch
    return super(LoginView, self).dispatch(*args, **kwargs)
  File "/usr/local/lib/python3.7/dist-packages/rest_framework/views.py", line 505, in dispatch
    response = self.handle_exception(exc)
  File "/usr/local/lib/python3.7/dist-packages/rest_framework/views.py", line 465, in handle_exception
    self.raise_uncaught_exception(exc)
  File "/usr/local/lib/python3.7/dist-packages/rest_framework/views.py", line 476, in raise_uncaught_exception
    raise exc
  File "/usr/local/lib/python3.7/dist-packages/rest_framework/views.py", line 502, in dispatch
    response = handler(request, *args, **kwargs)
  File "/usr/local/lib/python3.7/dist-packages/dj_rest_auth/views.py", line 109, in post
    self.serializer.is_valid(raise_exception=True)
  File "/usr/local/lib/python3.7/dist-packages/rest_framework/serializers.py", line 234, in is_valid
    self._validated_data = self.run_validation(self.initial_data)
  File "/usr/local/lib/python3.7/dist-packages/rest_framework/serializers.py", line 436, in run_validation
    value = self.validate(value)
  File "/usr/local/lib/python3.7/dist-packages/dj_rest_auth/serializers.py", line 110, in validate
    email_address = user.emailaddress_set.get(email=user.email)
  File "/usr/local/lib/python3.7/dist-packages/django/db/models/manager.py", line 82, in manager_method
    return getattr(self.get_queryset(), name)(*args, **kwargs)
  File "/usr/local/lib/python3.7/dist-packages/django/db/models/query.py", line 417, in get
    self.model._meta.object_name
allauth.account.models.EmailAddress.DoesNotExist: EmailAddress matching query does not exist.
2020/08/27 21:29:11 [notice] 1#1 process 50 exited with code 0
2020/08/27 21:29:11 [notice] 1#1 process 51 exited with code 0
2020/08/27 21:29:11 [notice] 1#1 process 52 exited with code 0
2020/08/27 21:29:17 [info] 21#21 discovery started
2020/08/27 21:29:17 [notice] 21#21 module: python 3.7.3 "/usr/lib/unit/modules/python3.7.unit.so"
2020/08/27 21:29:17 [info] 19#19 controller started
2020/08/27 21:29:17 [notice] 19#19 process 21 exited with code 0
2020/08/27 21:29:17 [info] 23#23 router started
2020/08/27 21:29:17 [info] 23#23 OpenSSL 1.1.1d  10 Sep 2019, 1010104f
2020/08/27 21:29:17 [info] 27#27 "django-app" application started
2020/08/27 21:29:18 [notice] 19#19 process 22 exited with code 0
2020/08/27 21:29:18 [notice] 19#19 process 23 exited with code 0
2020/08/27 21:29:18 [notice] 19#19 process 27 exited with code 0
2020/08/27 21:29:18 [info] 39#39 discovery started
2020/08/27 21:29:18 [notice] 39#39 module: python 3.7.3 "/usr/lib/unit/modules/python3.7.unit.so"
2020/08/27 21:29:18 [info] 1#1 controller started
2020/08/27 21:29:18 [notice] 1#1 process 39 exited with code 0
2020/08/27 21:29:18 [info] 41#41 router started
2020/08/27 21:29:18 [info] 41#41 OpenSSL 1.1.1d  10 Sep 2019, 1010104f
2020/08/27 21:29:18 [info] 42#42 "django-app" application started
Internal Server Error: /rest-auth/login/
Traceback (most recent call last):
  File "/usr/local/lib/python3.7/dist-packages/django/core/handlers/exception.py", line 34, in inner
    response = get_response(request)
  File "/usr/local/lib/python3.7/dist-packages/django/core/handlers/base.py", line 115, in _get_response
    response = self.process_exception_by_middleware(e, request)
  File "/usr/local/lib/python3.7/dist-packages/django/core/handlers/base.py", line 113, in _get_response
    response = wrapped_callback(request, *callback_args, **callback_kwargs)
  File "/usr/local/lib/python3.7/dist-packages/django/views/decorators/csrf.py", line 54, in wrapped_view
    return view_func(*args, **kwargs)
  File "/usr/local/lib/python3.7/dist-packages/django/views/generic/base.py", line 71, in view
    return self.dispatch(request, *args, **kwargs)
  File "/usr/local/lib/python3.7/dist-packages/django/utils/decorators.py", line 43, in _wrapper
    return bound_method(*args, **kwargs)
  File "/usr/local/lib/python3.7/dist-packages/django/views/decorators/debug.py", line 76, in sensitive_post_parameters_wrapper
    return view(request, *args, **kwargs)
  File "/usr/local/lib/python3.7/dist-packages/dj_rest_auth/views.py", line 47, in dispatch
    return super(LoginView, self).dispatch(*args, **kwargs)
  File "/usr/local/lib/python3.7/dist-packages/rest_framework/views.py", line 505, in dispatch
    response = self.handle_exception(exc)
  File "/usr/local/lib/python3.7/dist-packages/rest_framework/views.py", line 465, in handle_exception
    self.raise_uncaught_exception(exc)
  File "/usr/local/lib/python3.7/dist-packages/rest_framework/views.py", line 476, in raise_uncaught_exception
    raise exc
  File "/usr/local/lib/python3.7/dist-packages/rest_framework/views.py", line 502, in dispatch
    response = handler(request, *args, **kwargs)
  File "/usr/local/lib/python3.7/dist-packages/dj_rest_auth/views.py", line 109, in post
    self.serializer.is_valid(raise_exception=True)
  File "/usr/local/lib/python3.7/dist-packages/rest_framework/serializers.py", line 234, in is_valid
    self._validated_data = self.run_validation(self.initial_data)
  File "/usr/local/lib/python3.7/dist-packages/rest_framework/serializers.py", line 436, in run_validation
    value = self.validate(value)
  File "/usr/local/lib/python3.7/dist-packages/dj_rest_auth/serializers.py", line 110, in validate
    email_address = user.emailaddress_set.get(email=user.email)
  File "/usr/local/lib/python3.7/dist-packages/django/db/models/manager.py", line 82, in manager_method
    return getattr(self.get_queryset(), name)(*args, **kwargs)
  File "/usr/local/lib/python3.7/dist-packages/django/db/models/query.py", line 417, in get
    self.model._meta.object_name
allauth.account.models.EmailAddress.DoesNotExist: EmailAddress matching query does not exist.
Internal Server Error: /rest-auth/login/
Traceback (most recent call last):
  File "/usr/local/lib/python3.7/dist-packages/django/core/handlers/exception.py", line 34, in inner
    response = get_response(request)
  File "/usr/local/lib/python3.7/dist-packages/django/core/handlers/base.py", line 115, in _get_response
    response = self.process_exception_by_middleware(e, request)
  File "/usr/local/lib/python3.7/dist-packages/django/core/handlers/base.py", line 113, in _get_response
    response = wrapped_callback(request, *callback_args, **callback_kwargs)
  File "/usr/local/lib/python3.7/dist-packages/django/views/decorators/csrf.py", line 54, in wrapped_view
    return view_func(*args, **kwargs)
  File "/usr/local/lib/python3.7/dist-packages/django/views/generic/base.py", line 71, in view
    return self.dispatch(request, *args, **kwargs)
  File "/usr/local/lib/python3.7/dist-packages/django/utils/decorators.py", line 43, in _wrapper
    return bound_method(*args, **kwargs)
  File "/usr/local/lib/python3.7/dist-packages/django/views/decorators/debug.py", line 76, in sensitive_post_parameters_wrapper
    return view(request, *args, **kwargs)
  File "/usr/local/lib/python3.7/dist-packages/dj_rest_auth/views.py", line 47, in dispatch
    return super(LoginView, self).dispatch(*args, **kwargs)
  File "/usr/local/lib/python3.7/dist-packages/rest_framework/views.py", line 505, in dispatch
    response = self.handle_exception(exc)
  File "/usr/local/lib/python3.7/dist-packages/rest_framework/views.py", line 465, in handle_exception
    self.raise_uncaught_exception(exc)
  File "/usr/local/lib/python3.7/dist-packages/rest_framework/views.py", line 476, in raise_uncaught_exception
    raise exc
  File "/usr/local/lib/python3.7/dist-packages/rest_framework/views.py", line 502, in dispatch
    response = handler(request, *args, **kwargs)
  File "/usr/local/lib/python3.7/dist-packages/dj_rest_auth/views.py", line 109, in post
    self.serializer.is_valid(raise_exception=True)
  File "/usr/local/lib/python3.7/dist-packages/rest_framework/serializers.py", line 234, in is_valid
    self._validated_data = self.run_validation(self.initial_data)
  File "/usr/local/lib/python3.7/dist-packages/rest_framework/serializers.py", line 436, in run_validation
    value = self.validate(value)
  File "/usr/local/lib/python3.7/dist-packages/dj_rest_auth/serializers.py", line 110, in validate
    email_address = user.emailaddress_set.get(email=user.email)
  File "/usr/local/lib/python3.7/dist-packages/django/db/models/manager.py", line 82, in manager_method
    return getattr(self.get_queryset(), name)(*args, **kwargs)
  File "/usr/local/lib/python3.7/dist-packages/django/db/models/query.py", line 417, in get
    self.model._meta.object_name
allauth.account.models.EmailAddress.DoesNotExist: EmailAddress matching query does not exist.
Not Found: /favicon.ico
Internal Server Error: /rest-auth/login/
Traceback (most recent call last):
  File "/usr/local/lib/python3.7/dist-packages/django/core/handlers/exception.py", line 34, in inner
    response = get_response(request)
  File "/usr/local/lib/python3.7/dist-packages/django/core/handlers/base.py", line 115, in _get_response
    response = self.process_exception_by_middleware(e, request)
  File "/usr/local/lib/python3.7/dist-packages/django/core/handlers/base.py", line 113, in _get_response
    response = wrapped_callback(request, *callback_args, **callback_kwargs)
  File "/usr/local/lib/python3.7/dist-packages/django/views/decorators/csrf.py", line 54, in wrapped_view
    return view_func(*args, **kwargs)
  File "/usr/local/lib/python3.7/dist-packages/django/views/generic/base.py", line 71, in view
    return self.dispatch(request, *args, **kwargs)
  File "/usr/local/lib/python3.7/dist-packages/django/utils/decorators.py", line 43, in _wrapper
    return bound_method(*args, **kwargs)
  File "/usr/local/lib/python3.7/dist-packages/django/views/decorators/debug.py", line 76, in sensitive_post_parameters_wrapper
    return view(request, *args, **kwargs)
  File "/usr/local/lib/python3.7/dist-packages/dj_rest_auth/views.py", line 47, in dispatch
    return super(LoginView, self).dispatch(*args, **kwargs)
  File "/usr/local/lib/python3.7/dist-packages/rest_framework/views.py", line 505, in dispatch
    response = self.handle_exception(exc)
  File "/usr/local/lib/python3.7/dist-packages/rest_framework/views.py", line 465, in handle_exception
    self.raise_uncaught_exception(exc)
  File "/usr/local/lib/python3.7/dist-packages/rest_framework/views.py", line 476, in raise_uncaught_exception
    raise exc
  File "/usr/local/lib/python3.7/dist-packages/rest_framework/views.py", line 502, in dispatch
    response = handler(request, *args, **kwargs)
  File "/usr/local/lib/python3.7/dist-packages/dj_rest_auth/views.py", line 109, in post
    self.serializer.is_valid(raise_exception=True)
  File "/usr/local/lib/python3.7/dist-packages/rest_framework/serializers.py", line 234, in is_valid
    self._validated_data = self.run_validation(self.initial_data)
  File "/usr/local/lib/python3.7/dist-packages/rest_framework/serializers.py", line 436, in run_validation
    value = self.validate(value)
  File "/usr/local/lib/python3.7/dist-packages/dj_rest_auth/serializers.py", line 110, in validate
    email_address = user.emailaddress_set.get(email=user.email)
  File "/usr/local/lib/python3.7/dist-packages/django/db/models/manager.py", line 82, in manager_method
    return getattr(self.get_queryset(), name)(*args, **kwargs)
  File "/usr/local/lib/python3.7/dist-packages/django/db/models/query.py", line 417, in get
    self.model._meta.object_name
allauth.account.models.EmailAddress.DoesNotExist: EmailAddress matching query does not exist.
Not Found: /favicon.ico
Bad Request: /rest-auth/login/
Bad Request: /rest-auth/login/
Bad Request: /rest-auth/login/
Bad Request: /rest-auth/login/
Bad Request: /rest-auth/login/
Bad Request: /rest-auth/login/
Internal Server Error: /rest-auth/login/
Traceback (most recent call last):
  File "/usr/local/lib/python3.7/dist-packages/django/core/handlers/exception.py", line 34, in inner
    response = get_response(request)
  File "/usr/local/lib/python3.7/dist-packages/django/core/handlers/base.py", line 115, in _get_response
    response = self.process_exception_by_middleware(e, request)
  File "/usr/local/lib/python3.7/dist-packages/django/core/handlers/base.py", line 113, in _get_response
    response = wrapped_callback(request, *callback_args, **callback_kwargs)
  File "/usr/local/lib/python3.7/dist-packages/django/views/decorators/csrf.py", line 54, in wrapped_view
    return view_func(*args, **kwargs)
  File "/usr/local/lib/python3.7/dist-packages/django/views/generic/base.py", line 71, in view
    return self.dispatch(request, *args, **kwargs)
  File "/usr/local/lib/python3.7/dist-packages/django/utils/decorators.py", line 43, in _wrapper
    return bound_method(*args, **kwargs)
  File "/usr/local/lib/python3.7/dist-packages/django/views/decorators/debug.py", line 76, in sensitive_post_parameters_wrapper
    return view(request, *args, **kwargs)
  File "/usr/local/lib/python3.7/dist-packages/dj_rest_auth/views.py", line 47, in dispatch
    return super(LoginView, self).dispatch(*args, **kwargs)
  File "/usr/local/lib/python3.7/dist-packages/rest_framework/views.py", line 505, in dispatch
    response = self.handle_exception(exc)
  File "/usr/local/lib/python3.7/dist-packages/rest_framework/views.py", line 465, in handle_exception
    self.raise_uncaught_exception(exc)
  File "/usr/local/lib/python3.7/dist-packages/rest_framework/views.py", line 476, in raise_uncaught_exception
    raise exc
  File "/usr/local/lib/python3.7/dist-packages/rest_framework/views.py", line 502, in dispatch
    response = handler(request, *args, **kwargs)
  File "/usr/local/lib/python3.7/dist-packages/dj_rest_auth/views.py", line 109, in post
    self.serializer.is_valid(raise_exception=True)
  File "/usr/local/lib/python3.7/dist-packages/rest_framework/serializers.py", line 234, in is_valid
    self._validated_data = self.run_validation(self.initial_data)
  File "/usr/local/lib/python3.7/dist-packages/rest_framework/serializers.py", line 436, in run_validation
    value = self.validate(value)
  File "/usr/local/lib/python3.7/dist-packages/dj_rest_auth/serializers.py", line 110, in validate
    email_address = user.emailaddress_set.get(email=user.email)
  File "/usr/local/lib/python3.7/dist-packages/django/db/models/manager.py", line 82, in manager_method
    return getattr(self.get_queryset(), name)(*args, **kwargs)
  File "/usr/local/lib/python3.7/dist-packages/django/db/models/query.py", line 417, in get
    self.model._meta.object_name
allauth.account.models.EmailAddress.DoesNotExist: EmailAddress matching query does not exist.
2020/08/27 21:39:20 [notice] 1#1 process 40 exited with code 0
2020/08/27 21:39:20 [notice] 1#1 process 41 exited with code 0
2020/08/27 21:39:21 [notice] 1#1 process 42 exited with code 0
2020/08/27 22:10:40 [info] 20#20 discovery started
2020/08/27 22:10:40 [notice] 20#20 module: python 3.7.3 "/usr/lib/unit/modules/python3.7.unit.so"
2020/08/27 22:10:40 [info] 19#19 controller started
2020/08/27 22:10:40 [notice] 19#19 process 20 exited with code 0
2020/08/27 22:10:40 [info] 23#23 router started
2020/08/27 22:10:40 [info] 23#23 OpenSSL 1.1.1d  10 Sep 2019, 1010104f
2020/08/27 22:10:40 [info] 27#27 "django-app" application started
2020/08/27 22:10:41 [notice] 19#19 process 22 exited with code 0
2020/08/27 22:10:41 [notice] 19#19 process 23 exited with code 0
2020/08/27 22:10:41 [notice] 19#19 process 27 exited with code 0
2020/08/27 22:10:41 [info] 38#38 discovery started
2020/08/27 22:10:41 [notice] 38#38 module: python 3.7.3 "/usr/lib/unit/modules/python3.7.unit.so"
2020/08/27 22:10:41 [info] 1#1 controller started
2020/08/27 22:10:41 [notice] 1#1 process 38 exited with code 0
2020/08/27 22:10:41 [info] 40#40 router started
2020/08/27 22:10:41 [info] 40#40 OpenSSL 1.1.1d  10 Sep 2019, 1010104f
2020/08/27 22:10:41 [info] 41#41 "django-app" application started
2020/08/27 22:25:11 [notice] 1#1 process 39 exited with code 0
2020/08/27 22:25:11 [notice] 1#1 process 40 exited with code 0
2020/08/27 22:25:11 [notice] 1#1 process 41 exited with code 0
2020/08/27 22:25:31 [info] 18#18 discovery started
2020/08/27 22:25:31 [notice] 18#18 module: python 3.7.3 "/usr/lib/unit/modules/python3.7.unit.so"
2020/08/27 22:25:31 [info] 1#1 controller started
2020/08/27 22:25:31 [notice] 1#1 process 18 exited with code 0
2020/08/27 22:25:31 [info] 20#20 router started
2020/08/27 22:25:31 [info] 20#20 OpenSSL 1.1.1d  10 Sep 2019, 1010104f
2020/08/27 22:25:31 [info] 21#21 "django-app" application started
2020/08/27 22:25:49 [notice] 1#1 process 19 exited with code 0
2020/08/27 22:25:49 [notice] 1#1 process 20 exited with code 0
2020/08/27 22:25:49 [notice] 1#1 process 21 exited with code 0
2020/08/27 22:26:04 [info] 21#21 discovery started
2020/08/27 22:26:04 [notice] 21#21 module: python 3.7.3 "/usr/lib/unit/modules/python3.7.unit.so"
2020/08/27 22:26:04 [info] 20#20 controller started
2020/08/27 22:26:04 [notice] 20#20 process 21 exited with code 0
2020/08/27 22:26:04 [info] 24#24 router started
2020/08/27 22:26:04 [info] 24#24 OpenSSL 1.1.1d  10 Sep 2019, 1010104f
2020/08/27 22:26:04 [info] 28#28 "django-app" application started
2020/08/27 22:26:04 [notice] 20#20 process 23 exited with code 0
2020/08/27 22:26:04 [notice] 20#20 process 24 exited with code 0
2020/08/27 22:26:04 [notice] 20#20 process 28 exited with code 0
2020/08/27 22:26:04 [info] 39#39 discovery started
2020/08/27 22:26:04 [notice] 39#39 module: python 3.7.3 "/usr/lib/unit/modules/python3.7.unit.so"
2020/08/27 22:26:04 [info] 1#1 controller started
2020/08/27 22:26:04 [notice] 1#1 process 39 exited with code 0
2020/08/27 22:26:04 [info] 41#41 router started
2020/08/27 22:26:04 [info] 41#41 OpenSSL 1.1.1d  10 Sep 2019, 1010104f
2020/08/27 22:26:04 [info] 42#42 "django-app" application started
2020/08/27 22:26:08 [notice] 1#1 process 40 exited with code 0
2020/08/27 22:26:08 [notice] 1#1 process 41 exited with code 0
2020/08/27 22:26:08 [notice] 1#1 process 42 exited with code 0
2020/08/27 22:26:18 [info] 19#19 discovery started
2020/08/27 22:26:18 [notice] 19#19 module: python 3.7.3 "/usr/lib/unit/modules/python3.7.unit.so"
2020/08/27 22:26:18 [info] 1#1 controller started
2020/08/27 22:26:18 [notice] 1#1 process 19 exited with code 0
2020/08/27 22:26:18 [info] 21#21 router started
2020/08/27 22:26:18 [info] 21#21 OpenSSL 1.1.1d  10 Sep 2019, 1010104f
2020/08/27 22:26:18 [info] 22#22 "django-app" application started
2020/08/27 22:31:42 [notice] 1#1 process 20 exited with code 0
2020/08/27 22:31:42 [notice] 1#1 process 21 exited with code 0
2020/08/27 22:31:42 [notice] 1#1 process 22 exited with code 0
2020/08/27 22:42:12 [info] 26#26 discovery started
2020/08/27 22:42:12 [notice] 26#26 module: python 3.7.3 "/usr/lib/unit/modules/python3.7.unit.so"
2020/08/27 22:42:12 [info] 24#24 controller started
2020/08/27 22:42:12 [notice] 24#24 process 26 exited with code 0
2020/08/27 22:42:12 [info] 28#28 router started
2020/08/27 22:42:12 [info] 28#28 OpenSSL 1.1.1d  10 Sep 2019, 1010104f
2020/08/27 22:42:12 [info] 32#32 "django-app" application started
2020/08/27 22:42:14 [notice] 24#24 process 27 exited with code 0
2020/08/27 22:42:14 [notice] 24#24 process 28 exited with code 0
2020/08/27 22:42:14 [notice] 24#24 process 32 exited with code 0
2020/08/27 22:42:14 [info] 43#43 discovery started
2020/08/27 22:42:14 [notice] 43#43 module: python 3.7.3 "/usr/lib/unit/modules/python3.7.unit.so"
2020/08/27 22:42:14 [info] 1#1 controller started
2020/08/27 22:42:14 [notice] 1#1 process 43 exited with code 0
2020/08/27 22:42:14 [info] 45#45 router started
2020/08/27 22:42:14 [info] 45#45 OpenSSL 1.1.1d  10 Sep 2019, 1010104f
2020/08/27 22:42:14 [info] 46#46 "django-app" application started
2020/08/27 22:42:21 [notice] 1#1 process 44 exited with code 0
2020/08/27 22:42:21 [notice] 1#1 process 45 exited with code 0
2020/08/27 22:42:21 [notice] 1#1 process 46 exited with code 0
2020/08/27 22:42:33 [info] 21#21 discovery started
2020/08/27 22:42:33 [notice] 21#21 module: python 3.7.3 "/usr/lib/unit/modules/python3.7.unit.so"
2020/08/27 22:42:33 [info] 1#1 controller started
2020/08/27 22:42:33 [notice] 1#1 process 21 exited with code 0
2020/08/27 22:42:33 [info] 23#23 router started
2020/08/27 22:42:33 [info] 23#23 OpenSSL 1.1.1d  10 Sep 2019, 1010104f
2020/08/27 22:42:33 [info] 24#24 "django-app" application started
Not Found: /
2020/08/27 22:43:30 [notice] 1#1 process 22 exited with code 0
2020/08/27 22:43:30 [notice] 1#1 process 23 exited with code 0
2020/08/27 22:43:30 [notice] 1#1 process 24 exited with code 0
2020/08/27 23:04:38 [info] 20#20 discovery started
2020/08/27 23:04:38 [notice] 20#20 module: python 3.7.3 "/usr/lib/unit/modules/python3.7.unit.so"
2020/08/27 23:04:38 [info] 19#19 controller started
2020/08/27 23:04:38 [notice] 19#19 process 20 exited with code 0
2020/08/27 23:04:38 [info] 23#23 router started
2020/08/27 23:04:38 [info] 23#23 OpenSSL 1.1.1d  10 Sep 2019, 1010104f
2020/08/27 23:04:38 [info] 27#27 "django-app" application started
2020/08/27 23:04:39 [notice] 19#19 process 22 exited with code 0
2020/08/27 23:04:39 [notice] 19#19 process 23 exited with code 0
2020/08/27 23:04:40 [notice] 19#19 process 27 exited with code 0
2020/08/27 23:04:40 [info] 38#38 discovery started
2020/08/27 23:04:40 [notice] 38#38 module: python 3.7.3 "/usr/lib/unit/modules/python3.7.unit.so"
2020/08/27 23:04:40 [info] 1#1 controller started
2020/08/27 23:04:40 [notice] 1#1 process 38 exited with code 0
2020/08/27 23:04:40 [info] 40#40 router started
2020/08/27 23:04:40 [info] 40#40 OpenSSL 1.1.1d  10 Sep 2019, 1010104f
2020/08/27 23:04:40 [info] 41#41 "django-app" application started
2020/08/27 23:04:45 [notice] 1#1 process 39 exited with code 0
2020/08/27 23:04:45 [notice] 1#1 process 40 exited with code 0
2020/08/27 23:04:45 [notice] 1#1 process 41 exited with code 0
2020/08/27 23:05:11 [info] 18#18 discovery started
2020/08/27 23:05:11 [notice] 18#18 module: python 3.7.3 "/usr/lib/unit/modules/python3.7.unit.so"
2020/08/27 23:05:11 [info] 1#1 controller started
2020/08/27 23:05:11 [notice] 1#1 process 18 exited with code 0
2020/08/27 23:05:11 [info] 20#20 router started
2020/08/27 23:05:11 [info] 20#20 OpenSSL 1.1.1d  10 Sep 2019, 1010104f
2020/08/27 23:05:11 [info] 21#21 "django-app" application started
Not Found: /
Not Found: /favicon.ico
2020/08/27 23:05:33 [notice] 1#1 process 19 exited with code 0
2020/08/27 23:05:33 [notice] 1#1 process 20 exited with code 0
2020/08/27 23:05:33 [notice] 1#1 process 21 exited with code 0
2020/08/28 10:44:32 [info] 21#21 discovery started
2020/08/28 10:44:32 [notice] 21#21 module: python 3.7.3 "/usr/lib/unit/modules/python3.7.unit.so"
2020/08/28 10:44:32 [info] 20#20 controller started
2020/08/28 10:44:32 [notice] 20#20 process 21 exited with code 0
2020/08/28 10:44:32 [info] 24#24 router started
2020/08/28 10:44:32 [info] 24#24 OpenSSL 1.1.1d  10 Sep 2019, 1010104f
2020/08/28 10:44:32 [info] 28#28 "django-app" application started
2020/08/28 10:44:33 [notice] 20#20 process 23 exited with code 0
2020/08/28 10:44:33 [notice] 20#20 process 24 exited with code 0
2020/08/28 10:44:33 [notice] 20#20 process 28 exited with code 0
2020/08/28 10:44:33 [info] 39#39 discovery started
2020/08/28 10:44:33 [notice] 39#39 module: python 3.7.3 "/usr/lib/unit/modules/python3.7.unit.so"
2020/08/28 10:44:33 [info] 1#1 controller started
2020/08/28 10:44:33 [notice] 1#1 process 39 exited with code 0
2020/08/28 10:44:33 [info] 41#41 router started
2020/08/28 10:44:33 [info] 41#41 OpenSSL 1.1.1d  10 Sep 2019, 1010104f
2020/08/28 10:44:33 [info] 42#42 "django-app" application started
2020/08/28 10:44:51 [notice] 1#1 process 40 exited with code 0
2020/08/28 10:44:51 [notice] 1#1 process 41 exited with code 0
2020/08/28 10:44:51 [notice] 1#1 process 42 exited with code 0
